[2024-11-07T20:42:53.241+0000] {local_task_job_runner.py:123} INFO - ::group::Pre task execution logs
[2024-11-07T20:42:53.303+0000] {taskinstance.py:2613} INFO - Dependencies all met for dep_context=non-requeueable deps ti=<TaskInstance: dag_with_postgres_operator.insert_into_table scheduled__2024-07-20T00:00:00+00:00 [queued]>
[2024-11-07T20:42:53.334+0000] {taskinstance.py:2613} INFO - Dependencies all met for dep_context=requeueable deps ti=<TaskInstance: dag_with_postgres_operator.insert_into_table scheduled__2024-07-20T00:00:00+00:00 [queued]>
[2024-11-07T20:42:53.335+0000] {taskinstance.py:2866} INFO - Starting attempt 5 of 6
[2024-11-07T20:42:53.386+0000] {taskinstance.py:2889} INFO - Executing <Task(PostgresOperator): insert_into_table> on 2024-07-20 00:00:00+00:00
[2024-11-07T20:42:53.401+0000] {warnings.py:112} WARNING - /home/***/.local/lib/python3.12/site-packages/***/task/task_runner/standard_task_runner.py:70: DeprecationWarning: This process (pid=3410) is multi-threaded, use of fork() may lead to deadlocks in the child.
  pid = os.fork()

[2024-11-07T20:42:53.410+0000] {standard_task_runner.py:72} INFO - Started process 3425 to run task
[2024-11-07T20:42:53.411+0000] {standard_task_runner.py:104} INFO - Running: ['***', 'tasks', 'run', 'dag_with_postgres_operator', 'insert_into_table', 'scheduled__2024-07-20T00:00:00+00:00', '--job-id', '1331', '--raw', '--subdir', 'DAGS_FOLDER/postgres.py', '--cfg-path', '/tmp/tmpb6tsggyc']
[2024-11-07T20:42:53.431+0000] {standard_task_runner.py:105} INFO - Job 1331: Subtask insert_into_table
[2024-11-07T20:42:53.561+0000] {task_command.py:467} INFO - Running <TaskInstance: dag_with_postgres_operator.insert_into_table scheduled__2024-07-20T00:00:00+00:00 [running]> on host 3f85553e814e
[2024-11-07T20:42:53.785+0000] {taskinstance.py:3132} INFO - Exporting env vars: AIRFLOW_CTX_DAG_OWNER='sumit kumar' AIRFLOW_CTX_DAG_ID='dag_with_postgres_operator' AIRFLOW_CTX_TASK_ID='insert_into_table' AIRFLOW_CTX_EXECUTION_DATE='2024-07-20T00:00:00+00:00' AIRFLOW_CTX_TRY_NUMBER='5' AIRFLOW_CTX_DAG_RUN_ID='scheduled__2024-07-20T00:00:00+00:00'
[2024-11-07T20:42:53.788+0000] {logging_mixin.py:190} INFO - Task instance is in running state
[2024-11-07T20:42:53.789+0000] {logging_mixin.py:190} INFO -  Previous state of the Task instance: queued
[2024-11-07T20:42:53.798+0000] {logging_mixin.py:190} INFO - Current task name:insert_into_table state:running start_date:2024-11-07 20:42:53.306763+00:00
[2024-11-07T20:42:53.800+0000] {logging_mixin.py:190} INFO - Dag name:dag_with_postgres_operator and current dag run status:running
[2024-11-07T20:42:53.801+0000] {taskinstance.py:731} INFO - ::endgroup::
[2024-11-07T20:42:53.809+0000] {sql.py:278} INFO - Executing: 
            insert into Orders values(4,'No delivired')
        
[2024-11-07T20:42:53.834+0000] {base.py:84} INFO - Retrieving connection 'postgres_local'
[2024-11-07T20:42:53.864+0000] {base.py:84} INFO - Retrieving connection 'postgres_local'
[2024-11-07T20:42:53.890+0000] {sql.py:544} INFO - Running statement: 
            insert into Orders values(4,'No delivired')
        , parameters: None
[2024-11-07T20:42:53.899+0000] {taskinstance.py:3311} ERROR - Task failed with exception
Traceback (most recent call last):
  File "/home/airflow/.local/lib/python3.12/site-packages/airflow/models/taskinstance.py", line 767, in _execute_task
    result = _execute_callable(context=context, **execute_callable_kwargs)
             ^^^^^^^^^^^^^^^^^^^^^^^^^^^^^^^^^^^^^^^^^^^^^^^^^^^^^^^^^^^^^
  File "/home/airflow/.local/lib/python3.12/site-packages/airflow/models/taskinstance.py", line 733, in _execute_callable
    return ExecutionCallableRunner(
           ^^^^^^^^^^^^^^^^^^^^^^^^
  File "/home/airflow/.local/lib/python3.12/site-packages/airflow/utils/operator_helpers.py", line 252, in run
    return self.func(*args, **kwargs)
           ^^^^^^^^^^^^^^^^^^^^^^^^^^
  File "/home/airflow/.local/lib/python3.12/site-packages/airflow/models/baseoperator.py", line 417, in wrapper
    return func(self, *args, **kwargs)
           ^^^^^^^^^^^^^^^^^^^^^^^^^^^
  File "/home/airflow/.local/lib/python3.12/site-packages/airflow/providers/common/sql/operators/sql.py", line 284, in execute
    output = hook.run(
             ^^^^^^^^^
  File "/home/airflow/.local/lib/python3.12/site-packages/airflow/providers/common/sql/hooks/sql.py", line 489, in run
    self._run_command(cur, sql_statement, parameters)
  File "/home/airflow/.local/lib/python3.12/site-packages/airflow/providers/common/sql/hooks/sql.py", line 549, in _run_command
    cur.execute(sql_statement)
psycopg2.errors.UniqueViolation: duplicate key value violates unique constraint "orders_pkey"
DETAIL:  Key (orderid)=(4) already exists.

[2024-11-07T20:42:53.945+0000] {logging_mixin.py:190} INFO - Task instance in failure state
[2024-11-07T20:42:53.947+0000] {logging_mixin.py:190} INFO - Task start:2024-11-07 20:42:53.306763+00:00 end:2024-11-07 20:42:53.944599+00:00 duration:0.637836
[2024-11-07T20:42:53.956+0000] {logging_mixin.py:190} INFO - Task:<Task(PostgresOperator): insert_into_table> dag:<DAG: dag_with_postgres_operator> dagrun:<DagRun dag_with_postgres_operator @ 2024-07-20 00:00:00+00:00: scheduled__2024-07-20T00:00:00+00:00, state:running, queued_at: 2024-11-07 20:38:25.820069+00:00. externally triggered: False>
[2024-11-07T20:42:53.957+0000] {logging_mixin.py:190} INFO - Failure caused by duplicate key value violates unique constraint "orders_pkey"
DETAIL:  Key (orderid)=(4) already exists.
[2024-11-07T20:42:53.959+0000] {taskinstance.py:1225} INFO - Marking task as UP_FOR_RETRY. dag_id=dag_with_postgres_operator, task_id=insert_into_table, run_id=scheduled__2024-07-20T00:00:00+00:00, execution_date=20240720T000000, start_date=20241107T204253, end_date=20241107T204253
[2024-11-07T20:42:54.020+0000] {taskinstance.py:340} INFO - ::group::Post task execution logs
[2024-11-07T20:42:54.024+0000] {standard_task_runner.py:124} ERROR - Failed to execute job 1331 for task insert_into_table (duplicate key value violates unique constraint "orders_pkey"
DETAIL:  Key (orderid)=(4) already exists.
; 3425)
Traceback (most recent call last):
  File "/home/airflow/.local/lib/python3.12/site-packages/airflow/task/task_runner/standard_task_runner.py", line 117, in _start_by_fork
    ret = args.func(args, dag=self.dag)
          ^^^^^^^^^^^^^^^^^^^^^^^^^^^^^
  File "/home/airflow/.local/lib/python3.12/site-packages/airflow/cli/cli_config.py", line 49, in command
    return func(*args, **kwargs)
           ^^^^^^^^^^^^^^^^^^^^^
  File "/home/airflow/.local/lib/python3.12/site-packages/airflow/utils/cli.py", line 116, in wrapper
    return f(*args, **kwargs)
           ^^^^^^^^^^^^^^^^^^
  File "/home/airflow/.local/lib/python3.12/site-packages/airflow/cli/commands/task_command.py", line 483, in task_run
    task_return_code = _run_task_by_selected_method(args, _dag, ti)
                       ^^^^^^^^^^^^^^^^^^^^^^^^^^^^^^^^^^^^^^^^^^^^
  File "/home/airflow/.local/lib/python3.12/site-packages/airflow/cli/commands/task_command.py", line 256, in _run_task_by_selected_method
    return _run_raw_task(args, ti)
           ^^^^^^^^^^^^^^^^^^^^^^^
  File "/home/airflow/.local/lib/python3.12/site-packages/airflow/cli/commands/task_command.py", line 341, in _run_raw_task
    return ti._run_raw_task(
           ^^^^^^^^^^^^^^^^^
  File "/home/airflow/.local/lib/python3.12/site-packages/airflow/utils/session.py", line 97, in wrapper
    return func(*args, session=session, **kwargs)
           ^^^^^^^^^^^^^^^^^^^^^^^^^^^^^^^^^^^^^^
  File "/home/airflow/.local/lib/python3.12/site-packages/airflow/models/taskinstance.py", line 3005, in _run_raw_task
    return _run_raw_task(
           ^^^^^^^^^^^^^^
  File "/home/airflow/.local/lib/python3.12/site-packages/airflow/models/taskinstance.py", line 273, in _run_raw_task
    TaskInstance._execute_task_with_callbacks(
  File "/home/airflow/.local/lib/python3.12/site-packages/airflow/models/taskinstance.py", line 3159, in _execute_task_with_callbacks
    result = self._execute_task(context, task_orig)
             ^^^^^^^^^^^^^^^^^^^^^^^^^^^^^^^^^^^^^^
  File "/home/airflow/.local/lib/python3.12/site-packages/airflow/models/taskinstance.py", line 3183, in _execute_task
    return _execute_task(self, context, task_orig)
           ^^^^^^^^^^^^^^^^^^^^^^^^^^^^^^^^^^^^^^^
  File "/home/airflow/.local/lib/python3.12/site-packages/airflow/models/taskinstance.py", line 767, in _execute_task
    result = _execute_callable(context=context, **execute_callable_kwargs)
             ^^^^^^^^^^^^^^^^^^^^^^^^^^^^^^^^^^^^^^^^^^^^^^^^^^^^^^^^^^^^^
  File "/home/airflow/.local/lib/python3.12/site-packages/airflow/models/taskinstance.py", line 733, in _execute_callable
    return ExecutionCallableRunner(
           ^^^^^^^^^^^^^^^^^^^^^^^^
  File "/home/airflow/.local/lib/python3.12/site-packages/airflow/utils/operator_helpers.py", line 252, in run
    return self.func(*args, **kwargs)
           ^^^^^^^^^^^^^^^^^^^^^^^^^^
  File "/home/airflow/.local/lib/python3.12/site-packages/airflow/models/baseoperator.py", line 417, in wrapper
    return func(self, *args, **kwargs)
           ^^^^^^^^^^^^^^^^^^^^^^^^^^^
  File "/home/airflow/.local/lib/python3.12/site-packages/airflow/providers/common/sql/operators/sql.py", line 284, in execute
    output = hook.run(
             ^^^^^^^^^
  File "/home/airflow/.local/lib/python3.12/site-packages/airflow/providers/common/sql/hooks/sql.py", line 489, in run
    self._run_command(cur, sql_statement, parameters)
  File "/home/airflow/.local/lib/python3.12/site-packages/airflow/providers/common/sql/hooks/sql.py", line 549, in _run_command
    cur.execute(sql_statement)
psycopg2.errors.UniqueViolation: duplicate key value violates unique constraint "orders_pkey"
DETAIL:  Key (orderid)=(4) already exists.

[2024-11-07T20:42:54.068+0000] {local_task_job_runner.py:266} INFO - Task exited with return code 1
[2024-11-07T20:42:54.148+0000] {taskinstance.py:3895} INFO - 0 downstream tasks scheduled from follow-on schedule check
[2024-11-07T20:42:54.157+0000] {local_task_job_runner.py:245} INFO - ::endgroup::
[2024-11-09T21:28:13.886+0000] {local_task_job_runner.py:123} INFO - ::group::Pre task execution logs
[2024-11-09T21:28:13.964+0000] {taskinstance.py:2613} INFO - Dependencies all met for dep_context=non-requeueable deps ti=<TaskInstance: dag_with_postgres_operator.insert_into_table scheduled__2024-07-20T00:00:00+00:00 [queued]>
[2024-11-09T21:28:14.009+0000] {taskinstance.py:2613} INFO - Dependencies all met for dep_context=requeueable deps ti=<TaskInstance: dag_with_postgres_operator.insert_into_table scheduled__2024-07-20T00:00:00+00:00 [queued]>
[2024-11-09T21:28:14.012+0000] {taskinstance.py:2866} INFO - Starting attempt 5 of 6
[2024-11-09T21:28:14.085+0000] {taskinstance.py:2889} INFO - Executing <Task(PostgresOperator): insert_into_table> on 2024-07-20 00:00:00+00:00
[2024-11-09T21:28:14.116+0000] {warnings.py:112} WARNING - /home/***/.local/lib/python3.12/site-packages/***/task/task_runner/standard_task_runner.py:70: DeprecationWarning: This process (pid=1278) is multi-threaded, use of fork() may lead to deadlocks in the child.
  pid = os.fork()

[2024-11-09T21:28:14.130+0000] {standard_task_runner.py:72} INFO - Started process 1284 to run task
[2024-11-09T21:28:14.126+0000] {standard_task_runner.py:104} INFO - Running: ['***', 'tasks', 'run', 'dag_with_postgres_operator', 'insert_into_table', 'scheduled__2024-07-20T00:00:00+00:00', '--job-id', '1309', '--raw', '--subdir', 'DAGS_FOLDER/postgres.py', '--cfg-path', '/tmp/tmpkbyca_uv']
[2024-11-09T21:28:14.134+0000] {standard_task_runner.py:105} INFO - Job 1309: Subtask insert_into_table
[2024-11-09T21:28:14.353+0000] {task_command.py:467} INFO - Running <TaskInstance: dag_with_postgres_operator.insert_into_table scheduled__2024-07-20T00:00:00+00:00 [running]> on host d5d7d0963395
[2024-11-09T21:28:14.609+0000] {taskinstance.py:3132} INFO - Exporting env vars: AIRFLOW_CTX_DAG_OWNER='sumit kumar' AIRFLOW_CTX_DAG_ID='dag_with_postgres_operator' AIRFLOW_CTX_TASK_ID='insert_into_table' AIRFLOW_CTX_EXECUTION_DATE='2024-07-20T00:00:00+00:00' AIRFLOW_CTX_TRY_NUMBER='5' AIRFLOW_CTX_DAG_RUN_ID='scheduled__2024-07-20T00:00:00+00:00'
[2024-11-09T21:28:14.612+0000] {logging_mixin.py:190} INFO - Task instance is in running state
[2024-11-09T21:28:14.613+0000] {logging_mixin.py:190} INFO -  Previous state of the Task instance: queued
[2024-11-09T21:28:14.614+0000] {logging_mixin.py:190} INFO - Current task name:insert_into_table state:running start_date:2024-11-09 21:28:13.966070+00:00
[2024-11-09T21:28:14.615+0000] {logging_mixin.py:190} INFO - Dag name:dag_with_postgres_operator and current dag run status:running
[2024-11-09T21:28:14.616+0000] {taskinstance.py:731} INFO - ::endgroup::
[2024-11-09T21:28:14.618+0000] {sql.py:278} INFO - Executing: 
            insert into Orders values(4,'No delivired')
        
[2024-11-09T21:28:14.642+0000] {base.py:84} INFO - Retrieving connection 'postgres_local'
[2024-11-09T21:28:14.669+0000] {base.py:84} INFO - Retrieving connection 'postgres_local'
[2024-11-09T21:28:14.691+0000] {sql.py:544} INFO - Running statement: 
            insert into Orders values(4,'No delivired')
        , parameters: None
[2024-11-09T21:28:14.700+0000] {taskinstance.py:3311} ERROR - Task failed with exception
Traceback (most recent call last):
  File "/home/airflow/.local/lib/python3.12/site-packages/airflow/models/taskinstance.py", line 767, in _execute_task
    result = _execute_callable(context=context, **execute_callable_kwargs)
             ^^^^^^^^^^^^^^^^^^^^^^^^^^^^^^^^^^^^^^^^^^^^^^^^^^^^^^^^^^^^^
  File "/home/airflow/.local/lib/python3.12/site-packages/airflow/models/taskinstance.py", line 733, in _execute_callable
    return ExecutionCallableRunner(
           ^^^^^^^^^^^^^^^^^^^^^^^^
  File "/home/airflow/.local/lib/python3.12/site-packages/airflow/utils/operator_helpers.py", line 252, in run
    return self.func(*args, **kwargs)
           ^^^^^^^^^^^^^^^^^^^^^^^^^^
  File "/home/airflow/.local/lib/python3.12/site-packages/airflow/models/baseoperator.py", line 417, in wrapper
    return func(self, *args, **kwargs)
           ^^^^^^^^^^^^^^^^^^^^^^^^^^^
  File "/home/airflow/.local/lib/python3.12/site-packages/airflow/providers/common/sql/operators/sql.py", line 284, in execute
    output = hook.run(
             ^^^^^^^^^
  File "/home/airflow/.local/lib/python3.12/site-packages/airflow/providers/common/sql/hooks/sql.py", line 489, in run
    self._run_command(cur, sql_statement, parameters)
  File "/home/airflow/.local/lib/python3.12/site-packages/airflow/providers/common/sql/hooks/sql.py", line 549, in _run_command
    cur.execute(sql_statement)
psycopg2.errors.UniqueViolation: duplicate key value violates unique constraint "orders_pkey"
DETAIL:  Key (orderid)=(4) already exists.

[2024-11-09T21:28:14.760+0000] {logging_mixin.py:190} INFO - Task instance in failure state
[2024-11-09T21:28:14.762+0000] {logging_mixin.py:190} INFO - Task start:2024-11-09 21:28:13.966070+00:00 end:2024-11-09 21:28:14.758583+00:00 duration:0.792513
[2024-11-09T21:28:14.764+0000] {logging_mixin.py:190} INFO - Task:<Task(PostgresOperator): insert_into_table> dag:<DAG: dag_with_postgres_operator> dagrun:<DagRun dag_with_postgres_operator @ 2024-07-20 00:00:00+00:00: scheduled__2024-07-20T00:00:00+00:00, state:running, queued_at: 2024-11-09 21:23:24.033118+00:00. externally triggered: False>
[2024-11-09T21:28:14.765+0000] {logging_mixin.py:190} INFO - Failure caused by duplicate key value violates unique constraint "orders_pkey"
DETAIL:  Key (orderid)=(4) already exists.
[2024-11-09T21:28:14.766+0000] {taskinstance.py:1225} INFO - Marking task as UP_FOR_RETRY. dag_id=dag_with_postgres_operator, task_id=insert_into_table, run_id=scheduled__2024-07-20T00:00:00+00:00, execution_date=20240720T000000, start_date=20241109T212813, end_date=20241109T212814
[2024-11-09T21:28:14.827+0000] {taskinstance.py:340} INFO - ::group::Post task execution logs
[2024-11-09T21:28:14.830+0000] {standard_task_runner.py:124} ERROR - Failed to execute job 1309 for task insert_into_table (duplicate key value violates unique constraint "orders_pkey"
DETAIL:  Key (orderid)=(4) already exists.
; 1284)
Traceback (most recent call last):
  File "/home/airflow/.local/lib/python3.12/site-packages/airflow/task/task_runner/standard_task_runner.py", line 117, in _start_by_fork
    ret = args.func(args, dag=self.dag)
          ^^^^^^^^^^^^^^^^^^^^^^^^^^^^^
  File "/home/airflow/.local/lib/python3.12/site-packages/airflow/cli/cli_config.py", line 49, in command
    return func(*args, **kwargs)
           ^^^^^^^^^^^^^^^^^^^^^
  File "/home/airflow/.local/lib/python3.12/site-packages/airflow/utils/cli.py", line 116, in wrapper
    return f(*args, **kwargs)
           ^^^^^^^^^^^^^^^^^^
  File "/home/airflow/.local/lib/python3.12/site-packages/airflow/cli/commands/task_command.py", line 483, in task_run
    task_return_code = _run_task_by_selected_method(args, _dag, ti)
                       ^^^^^^^^^^^^^^^^^^^^^^^^^^^^^^^^^^^^^^^^^^^^
  File "/home/airflow/.local/lib/python3.12/site-packages/airflow/cli/commands/task_command.py", line 256, in _run_task_by_selected_method
    return _run_raw_task(args, ti)
           ^^^^^^^^^^^^^^^^^^^^^^^
  File "/home/airflow/.local/lib/python3.12/site-packages/airflow/cli/commands/task_command.py", line 341, in _run_raw_task
    return ti._run_raw_task(
           ^^^^^^^^^^^^^^^^^
  File "/home/airflow/.local/lib/python3.12/site-packages/airflow/utils/session.py", line 97, in wrapper
    return func(*args, session=session, **kwargs)
           ^^^^^^^^^^^^^^^^^^^^^^^^^^^^^^^^^^^^^^
  File "/home/airflow/.local/lib/python3.12/site-packages/airflow/models/taskinstance.py", line 3005, in _run_raw_task
    return _run_raw_task(
           ^^^^^^^^^^^^^^
  File "/home/airflow/.local/lib/python3.12/site-packages/airflow/models/taskinstance.py", line 273, in _run_raw_task
    TaskInstance._execute_task_with_callbacks(
  File "/home/airflow/.local/lib/python3.12/site-packages/airflow/models/taskinstance.py", line 3159, in _execute_task_with_callbacks
    result = self._execute_task(context, task_orig)
             ^^^^^^^^^^^^^^^^^^^^^^^^^^^^^^^^^^^^^^
  File "/home/airflow/.local/lib/python3.12/site-packages/airflow/models/taskinstance.py", line 3183, in _execute_task
    return _execute_task(self, context, task_orig)
           ^^^^^^^^^^^^^^^^^^^^^^^^^^^^^^^^^^^^^^^
  File "/home/airflow/.local/lib/python3.12/site-packages/airflow/models/taskinstance.py", line 767, in _execute_task
    result = _execute_callable(context=context, **execute_callable_kwargs)
             ^^^^^^^^^^^^^^^^^^^^^^^^^^^^^^^^^^^^^^^^^^^^^^^^^^^^^^^^^^^^^
  File "/home/airflow/.local/lib/python3.12/site-packages/airflow/models/taskinstance.py", line 733, in _execute_callable
    return ExecutionCallableRunner(
           ^^^^^^^^^^^^^^^^^^^^^^^^
  File "/home/airflow/.local/lib/python3.12/site-packages/airflow/utils/operator_helpers.py", line 252, in run
    return self.func(*args, **kwargs)
           ^^^^^^^^^^^^^^^^^^^^^^^^^^
  File "/home/airflow/.local/lib/python3.12/site-packages/airflow/models/baseoperator.py", line 417, in wrapper
    return func(self, *args, **kwargs)
           ^^^^^^^^^^^^^^^^^^^^^^^^^^^
  File "/home/airflow/.local/lib/python3.12/site-packages/airflow/providers/common/sql/operators/sql.py", line 284, in execute
    output = hook.run(
             ^^^^^^^^^
  File "/home/airflow/.local/lib/python3.12/site-packages/airflow/providers/common/sql/hooks/sql.py", line 489, in run
    self._run_command(cur, sql_statement, parameters)
  File "/home/airflow/.local/lib/python3.12/site-packages/airflow/providers/common/sql/hooks/sql.py", line 549, in _run_command
    cur.execute(sql_statement)
psycopg2.errors.UniqueViolation: duplicate key value violates unique constraint "orders_pkey"
DETAIL:  Key (orderid)=(4) already exists.

[2024-11-09T21:28:14.888+0000] {local_task_job_runner.py:266} INFO - Task exited with return code 1
[2024-11-09T21:28:14.959+0000] {taskinstance.py:3895} INFO - 0 downstream tasks scheduled from follow-on schedule check
[2024-11-09T21:28:14.964+0000] {local_task_job_runner.py:245} INFO - ::endgroup::
