[2024-11-07T20:24:15.558+0000] {local_task_job_runner.py:123} INFO - ::group::Pre task execution logs
[2024-11-07T20:24:15.590+0000] {taskinstance.py:2613} INFO - Dependencies all met for dep_context=non-requeueable deps ti=<TaskInstance: dag_with_postgres_operator.insert_into_table scheduled__2024-06-09T00:00:00+00:00 [queued]>
[2024-11-07T20:24:15.607+0000] {taskinstance.py:2613} INFO - Dependencies all met for dep_context=requeueable deps ti=<TaskInstance: dag_with_postgres_operator.insert_into_table scheduled__2024-06-09T00:00:00+00:00 [queued]>
[2024-11-07T20:24:15.608+0000] {taskinstance.py:2866} INFO - Starting attempt 3 of 6
[2024-11-07T20:24:15.639+0000] {taskinstance.py:2889} INFO - Executing <Task(PostgresOperator): insert_into_table> on 2024-06-09 00:00:00+00:00
[2024-11-07T20:24:15.654+0000] {warnings.py:112} WARNING - /home/***/.local/lib/python3.12/site-packages/***/task/task_runner/standard_task_runner.py:70: DeprecationWarning: This process (pid=1723) is multi-threaded, use of fork() may lead to deadlocks in the child.
  pid = os.fork()

[2024-11-07T20:24:15.658+0000] {standard_task_runner.py:72} INFO - Started process 1732 to run task
[2024-11-07T20:24:15.657+0000] {standard_task_runner.py:104} INFO - Running: ['***', 'tasks', 'run', 'dag_with_postgres_operator', 'insert_into_table', 'scheduled__2024-06-09T00:00:00+00:00', '--job-id', '965', '--raw', '--subdir', 'DAGS_FOLDER/postgres.py', '--cfg-path', '/tmp/tmpkkosacng']
[2024-11-07T20:24:15.659+0000] {standard_task_runner.py:105} INFO - Job 965: Subtask insert_into_table
[2024-11-07T20:24:15.739+0000] {task_command.py:467} INFO - Running <TaskInstance: dag_with_postgres_operator.insert_into_table scheduled__2024-06-09T00:00:00+00:00 [running]> on host 3f85553e814e
[2024-11-07T20:24:16.258+0000] {taskinstance.py:3132} INFO - Exporting env vars: AIRFLOW_CTX_DAG_OWNER='sumit kumar' AIRFLOW_CTX_DAG_ID='dag_with_postgres_operator' AIRFLOW_CTX_TASK_ID='insert_into_table' AIRFLOW_CTX_EXECUTION_DATE='2024-06-09T00:00:00+00:00' AIRFLOW_CTX_TRY_NUMBER='3' AIRFLOW_CTX_DAG_RUN_ID='scheduled__2024-06-09T00:00:00+00:00'
[2024-11-07T20:24:16.261+0000] {logging_mixin.py:190} INFO - Task instance is in running state
[2024-11-07T20:24:16.264+0000] {logging_mixin.py:190} INFO -  Previous state of the Task instance: queued
[2024-11-07T20:24:16.265+0000] {logging_mixin.py:190} INFO - Current task name:insert_into_table state:running start_date:2024-11-07 20:24:15.591147+00:00
[2024-11-07T20:24:16.271+0000] {logging_mixin.py:190} INFO - Dag name:dag_with_postgres_operator and current dag run status:running
[2024-11-07T20:24:16.272+0000] {taskinstance.py:731} INFO - ::endgroup::
[2024-11-07T20:24:16.273+0000] {sql.py:278} INFO - Executing: 
            insert into Orders values(4,'No delivired')
        
[2024-11-07T20:24:16.292+0000] {base.py:84} INFO - Retrieving connection 'postgres_local'
[2024-11-07T20:24:16.316+0000] {base.py:84} INFO - Retrieving connection 'postgres_local'
[2024-11-07T20:24:16.337+0000] {sql.py:544} INFO - Running statement: 
            insert into Orders values(4,'No delivired')
        , parameters: None
[2024-11-07T20:24:16.343+0000] {taskinstance.py:3311} ERROR - Task failed with exception
Traceback (most recent call last):
  File "/home/airflow/.local/lib/python3.12/site-packages/airflow/models/taskinstance.py", line 767, in _execute_task
    result = _execute_callable(context=context, **execute_callable_kwargs)
             ^^^^^^^^^^^^^^^^^^^^^^^^^^^^^^^^^^^^^^^^^^^^^^^^^^^^^^^^^^^^^
  File "/home/airflow/.local/lib/python3.12/site-packages/airflow/models/taskinstance.py", line 733, in _execute_callable
    return ExecutionCallableRunner(
           ^^^^^^^^^^^^^^^^^^^^^^^^
  File "/home/airflow/.local/lib/python3.12/site-packages/airflow/utils/operator_helpers.py", line 252, in run
    return self.func(*args, **kwargs)
           ^^^^^^^^^^^^^^^^^^^^^^^^^^
  File "/home/airflow/.local/lib/python3.12/site-packages/airflow/models/baseoperator.py", line 417, in wrapper
    return func(self, *args, **kwargs)
           ^^^^^^^^^^^^^^^^^^^^^^^^^^^
  File "/home/airflow/.local/lib/python3.12/site-packages/airflow/providers/common/sql/operators/sql.py", line 284, in execute
    output = hook.run(
             ^^^^^^^^^
  File "/home/airflow/.local/lib/python3.12/site-packages/airflow/providers/common/sql/hooks/sql.py", line 489, in run
    self._run_command(cur, sql_statement, parameters)
  File "/home/airflow/.local/lib/python3.12/site-packages/airflow/providers/common/sql/hooks/sql.py", line 549, in _run_command
    cur.execute(sql_statement)
psycopg2.errors.UniqueViolation: duplicate key value violates unique constraint "orders_pkey"
DETAIL:  Key (orderid)=(4) already exists.

[2024-11-07T20:24:16.370+0000] {logging_mixin.py:190} INFO - Task instance in failure state
[2024-11-07T20:24:16.371+0000] {logging_mixin.py:190} INFO - Task start:2024-11-07 20:24:15.591147+00:00 end:2024-11-07 20:24:16.369928+00:00 duration:0.778781
[2024-11-07T20:24:16.372+0000] {logging_mixin.py:190} INFO - Task:<Task(PostgresOperator): insert_into_table> dag:<DAG: dag_with_postgres_operator> dagrun:<DagRun dag_with_postgres_operator @ 2024-06-09 00:00:00+00:00: scheduled__2024-06-09T00:00:00+00:00, state:running, queued_at: 2024-11-07 20:22:00.531780+00:00. externally triggered: False>
[2024-11-07T20:24:16.374+0000] {logging_mixin.py:190} INFO - Failure caused by duplicate key value violates unique constraint "orders_pkey"
DETAIL:  Key (orderid)=(4) already exists.
[2024-11-07T20:24:16.375+0000] {taskinstance.py:1225} INFO - Marking task as UP_FOR_RETRY. dag_id=dag_with_postgres_operator, task_id=insert_into_table, run_id=scheduled__2024-06-09T00:00:00+00:00, execution_date=20240609T000000, start_date=20241107T202415, end_date=20241107T202416
[2024-11-07T20:24:16.567+0000] {taskinstance.py:340} INFO - ::group::Post task execution logs
[2024-11-07T20:24:16.568+0000] {standard_task_runner.py:124} ERROR - Failed to execute job 965 for task insert_into_table (duplicate key value violates unique constraint "orders_pkey"
DETAIL:  Key (orderid)=(4) already exists.
; 1732)
Traceback (most recent call last):
  File "/home/airflow/.local/lib/python3.12/site-packages/airflow/task/task_runner/standard_task_runner.py", line 117, in _start_by_fork
    ret = args.func(args, dag=self.dag)
          ^^^^^^^^^^^^^^^^^^^^^^^^^^^^^
  File "/home/airflow/.local/lib/python3.12/site-packages/airflow/cli/cli_config.py", line 49, in command
    return func(*args, **kwargs)
           ^^^^^^^^^^^^^^^^^^^^^
  File "/home/airflow/.local/lib/python3.12/site-packages/airflow/utils/cli.py", line 116, in wrapper
    return f(*args, **kwargs)
           ^^^^^^^^^^^^^^^^^^
  File "/home/airflow/.local/lib/python3.12/site-packages/airflow/cli/commands/task_command.py", line 483, in task_run
    task_return_code = _run_task_by_selected_method(args, _dag, ti)
                       ^^^^^^^^^^^^^^^^^^^^^^^^^^^^^^^^^^^^^^^^^^^^
  File "/home/airflow/.local/lib/python3.12/site-packages/airflow/cli/commands/task_command.py", line 256, in _run_task_by_selected_method
    return _run_raw_task(args, ti)
           ^^^^^^^^^^^^^^^^^^^^^^^
  File "/home/airflow/.local/lib/python3.12/site-packages/airflow/cli/commands/task_command.py", line 341, in _run_raw_task
    return ti._run_raw_task(
           ^^^^^^^^^^^^^^^^^
  File "/home/airflow/.local/lib/python3.12/site-packages/airflow/utils/session.py", line 97, in wrapper
    return func(*args, session=session, **kwargs)
           ^^^^^^^^^^^^^^^^^^^^^^^^^^^^^^^^^^^^^^
  File "/home/airflow/.local/lib/python3.12/site-packages/airflow/models/taskinstance.py", line 3005, in _run_raw_task
    return _run_raw_task(
           ^^^^^^^^^^^^^^
  File "/home/airflow/.local/lib/python3.12/site-packages/airflow/models/taskinstance.py", line 273, in _run_raw_task
    TaskInstance._execute_task_with_callbacks(
  File "/home/airflow/.local/lib/python3.12/site-packages/airflow/models/taskinstance.py", line 3159, in _execute_task_with_callbacks
    result = self._execute_task(context, task_orig)
             ^^^^^^^^^^^^^^^^^^^^^^^^^^^^^^^^^^^^^^
  File "/home/airflow/.local/lib/python3.12/site-packages/airflow/models/taskinstance.py", line 3183, in _execute_task
    return _execute_task(self, context, task_orig)
           ^^^^^^^^^^^^^^^^^^^^^^^^^^^^^^^^^^^^^^^
  File "/home/airflow/.local/lib/python3.12/site-packages/airflow/models/taskinstance.py", line 767, in _execute_task
    result = _execute_callable(context=context, **execute_callable_kwargs)
             ^^^^^^^^^^^^^^^^^^^^^^^^^^^^^^^^^^^^^^^^^^^^^^^^^^^^^^^^^^^^^
  File "/home/airflow/.local/lib/python3.12/site-packages/airflow/models/taskinstance.py", line 733, in _execute_callable
    return ExecutionCallableRunner(
           ^^^^^^^^^^^^^^^^^^^^^^^^
  File "/home/airflow/.local/lib/python3.12/site-packages/airflow/utils/operator_helpers.py", line 252, in run
    return self.func(*args, **kwargs)
           ^^^^^^^^^^^^^^^^^^^^^^^^^^
  File "/home/airflow/.local/lib/python3.12/site-packages/airflow/models/baseoperator.py", line 417, in wrapper
    return func(self, *args, **kwargs)
           ^^^^^^^^^^^^^^^^^^^^^^^^^^^
  File "/home/airflow/.local/lib/python3.12/site-packages/airflow/providers/common/sql/operators/sql.py", line 284, in execute
    output = hook.run(
             ^^^^^^^^^
  File "/home/airflow/.local/lib/python3.12/site-packages/airflow/providers/common/sql/hooks/sql.py", line 489, in run
    self._run_command(cur, sql_statement, parameters)
  File "/home/airflow/.local/lib/python3.12/site-packages/airflow/providers/common/sql/hooks/sql.py", line 549, in _run_command
    cur.execute(sql_statement)
psycopg2.errors.UniqueViolation: duplicate key value violates unique constraint "orders_pkey"
DETAIL:  Key (orderid)=(4) already exists.

[2024-11-07T20:24:16.638+0000] {local_task_job_runner.py:266} INFO - Task exited with return code 1
[2024-11-07T20:24:16.683+0000] {taskinstance.py:3895} INFO - 0 downstream tasks scheduled from follow-on schedule check
[2024-11-07T20:24:16.686+0000] {local_task_job_runner.py:245} INFO - ::endgroup::
[2024-11-09T21:10:55.612+0000] {local_task_job_runner.py:123} INFO - ::group::Pre task execution logs
[2024-11-09T21:10:55.649+0000] {taskinstance.py:2613} INFO - Dependencies all met for dep_context=non-requeueable deps ti=<TaskInstance: dag_with_postgres_operator.insert_into_table scheduled__2024-06-09T00:00:00+00:00 [queued]>
[2024-11-09T21:10:55.670+0000] {taskinstance.py:2613} INFO - Dependencies all met for dep_context=requeueable deps ti=<TaskInstance: dag_with_postgres_operator.insert_into_table scheduled__2024-06-09T00:00:00+00:00 [queued]>
[2024-11-09T21:10:55.671+0000] {taskinstance.py:2866} INFO - Starting attempt 3 of 6
[2024-11-09T21:10:55.714+0000] {taskinstance.py:2889} INFO - Executing <Task(PostgresOperator): insert_into_table> on 2024-06-09 00:00:00+00:00
[2024-11-09T21:10:55.731+0000] {warnings.py:112} WARNING - /home/***/.local/lib/python3.12/site-packages/***/task/task_runner/standard_task_runner.py:70: DeprecationWarning: This process (pid=365) is multi-threaded, use of fork() may lead to deadlocks in the child.
  pid = os.fork()

[2024-11-09T21:10:55.736+0000] {standard_task_runner.py:72} INFO - Started process 371 to run task
[2024-11-09T21:10:55.736+0000] {standard_task_runner.py:104} INFO - Running: ['***', 'tasks', 'run', 'dag_with_postgres_operator', 'insert_into_table', 'scheduled__2024-06-09T00:00:00+00:00', '--job-id', '1041', '--raw', '--subdir', 'DAGS_FOLDER/postgres.py', '--cfg-path', '/tmp/tmp2ozm_0xt']
[2024-11-09T21:10:55.740+0000] {standard_task_runner.py:105} INFO - Job 1041: Subtask insert_into_table
[2024-11-09T21:10:55.878+0000] {task_command.py:467} INFO - Running <TaskInstance: dag_with_postgres_operator.insert_into_table scheduled__2024-06-09T00:00:00+00:00 [running]> on host ca62e4f241b9
[2024-11-09T21:10:56.180+0000] {taskinstance.py:3132} INFO - Exporting env vars: AIRFLOW_CTX_DAG_OWNER='sumit kumar' AIRFLOW_CTX_DAG_ID='dag_with_postgres_operator' AIRFLOW_CTX_TASK_ID='insert_into_table' AIRFLOW_CTX_EXECUTION_DATE='2024-06-09T00:00:00+00:00' AIRFLOW_CTX_TRY_NUMBER='3' AIRFLOW_CTX_DAG_RUN_ID='scheduled__2024-06-09T00:00:00+00:00'
[2024-11-09T21:10:56.184+0000] {logging_mixin.py:190} INFO - Task instance is in running state
[2024-11-09T21:10:56.187+0000] {logging_mixin.py:190} INFO -  Previous state of the Task instance: queued
[2024-11-09T21:10:56.189+0000] {logging_mixin.py:190} INFO - Current task name:insert_into_table state:running start_date:2024-11-09 21:10:55.650220+00:00
[2024-11-09T21:10:56.190+0000] {logging_mixin.py:190} INFO - Dag name:dag_with_postgres_operator and current dag run status:running
[2024-11-09T21:10:56.191+0000] {taskinstance.py:731} INFO - ::endgroup::
[2024-11-09T21:10:56.192+0000] {sql.py:278} INFO - Executing: 
            insert into Orders values(4,'No delivired')
        
[2024-11-09T21:10:56.214+0000] {base.py:84} INFO - Retrieving connection 'postgres_local'
[2024-11-09T21:10:56.245+0000] {base.py:84} INFO - Retrieving connection 'postgres_local'
[2024-11-09T21:10:56.271+0000] {sql.py:544} INFO - Running statement: 
            insert into Orders values(4,'No delivired')
        , parameters: None
[2024-11-09T21:10:56.284+0000] {taskinstance.py:3311} ERROR - Task failed with exception
Traceback (most recent call last):
  File "/home/airflow/.local/lib/python3.12/site-packages/airflow/models/taskinstance.py", line 767, in _execute_task
    result = _execute_callable(context=context, **execute_callable_kwargs)
             ^^^^^^^^^^^^^^^^^^^^^^^^^^^^^^^^^^^^^^^^^^^^^^^^^^^^^^^^^^^^^
  File "/home/airflow/.local/lib/python3.12/site-packages/airflow/models/taskinstance.py", line 733, in _execute_callable
    return ExecutionCallableRunner(
           ^^^^^^^^^^^^^^^^^^^^^^^^
  File "/home/airflow/.local/lib/python3.12/site-packages/airflow/utils/operator_helpers.py", line 252, in run
    return self.func(*args, **kwargs)
           ^^^^^^^^^^^^^^^^^^^^^^^^^^
  File "/home/airflow/.local/lib/python3.12/site-packages/airflow/models/baseoperator.py", line 417, in wrapper
    return func(self, *args, **kwargs)
           ^^^^^^^^^^^^^^^^^^^^^^^^^^^
  File "/home/airflow/.local/lib/python3.12/site-packages/airflow/providers/common/sql/operators/sql.py", line 284, in execute
    output = hook.run(
             ^^^^^^^^^
  File "/home/airflow/.local/lib/python3.12/site-packages/airflow/providers/common/sql/hooks/sql.py", line 489, in run
    self._run_command(cur, sql_statement, parameters)
  File "/home/airflow/.local/lib/python3.12/site-packages/airflow/providers/common/sql/hooks/sql.py", line 549, in _run_command
    cur.execute(sql_statement)
psycopg2.errors.UniqueViolation: duplicate key value violates unique constraint "orders_pkey"
DETAIL:  Key (orderid)=(4) already exists.

[2024-11-09T21:10:56.341+0000] {logging_mixin.py:190} INFO - Task instance in failure state
[2024-11-09T21:10:56.343+0000] {logging_mixin.py:190} INFO - Task start:2024-11-09 21:10:55.650220+00:00 end:2024-11-09 21:10:56.339405+00:00 duration:0.689185
[2024-11-09T21:10:56.344+0000] {logging_mixin.py:190} INFO - Task:<Task(PostgresOperator): insert_into_table> dag:<DAG: dag_with_postgres_operator> dagrun:<DagRun dag_with_postgres_operator @ 2024-06-09 00:00:00+00:00: scheduled__2024-06-09T00:00:00+00:00, state:running, queued_at: 2024-11-09 21:08:25.685741+00:00. externally triggered: False>
[2024-11-09T21:10:56.346+0000] {logging_mixin.py:190} INFO - Failure caused by duplicate key value violates unique constraint "orders_pkey"
DETAIL:  Key (orderid)=(4) already exists.
[2024-11-09T21:10:56.347+0000] {taskinstance.py:1225} INFO - Marking task as UP_FOR_RETRY. dag_id=dag_with_postgres_operator, task_id=insert_into_table, run_id=scheduled__2024-06-09T00:00:00+00:00, execution_date=20240609T000000, start_date=20241109T211055, end_date=20241109T211056
[2024-11-09T21:10:56.402+0000] {taskinstance.py:340} INFO - ::group::Post task execution logs
[2024-11-09T21:10:56.404+0000] {standard_task_runner.py:124} ERROR - Failed to execute job 1041 for task insert_into_table (duplicate key value violates unique constraint "orders_pkey"
DETAIL:  Key (orderid)=(4) already exists.
; 371)
Traceback (most recent call last):
  File "/home/airflow/.local/lib/python3.12/site-packages/airflow/task/task_runner/standard_task_runner.py", line 117, in _start_by_fork
    ret = args.func(args, dag=self.dag)
          ^^^^^^^^^^^^^^^^^^^^^^^^^^^^^
  File "/home/airflow/.local/lib/python3.12/site-packages/airflow/cli/cli_config.py", line 49, in command
    return func(*args, **kwargs)
           ^^^^^^^^^^^^^^^^^^^^^
  File "/home/airflow/.local/lib/python3.12/site-packages/airflow/utils/cli.py", line 116, in wrapper
    return f(*args, **kwargs)
           ^^^^^^^^^^^^^^^^^^
  File "/home/airflow/.local/lib/python3.12/site-packages/airflow/cli/commands/task_command.py", line 483, in task_run
    task_return_code = _run_task_by_selected_method(args, _dag, ti)
                       ^^^^^^^^^^^^^^^^^^^^^^^^^^^^^^^^^^^^^^^^^^^^
  File "/home/airflow/.local/lib/python3.12/site-packages/airflow/cli/commands/task_command.py", line 256, in _run_task_by_selected_method
    return _run_raw_task(args, ti)
           ^^^^^^^^^^^^^^^^^^^^^^^
  File "/home/airflow/.local/lib/python3.12/site-packages/airflow/cli/commands/task_command.py", line 341, in _run_raw_task
    return ti._run_raw_task(
           ^^^^^^^^^^^^^^^^^
  File "/home/airflow/.local/lib/python3.12/site-packages/airflow/utils/session.py", line 97, in wrapper
    return func(*args, session=session, **kwargs)
           ^^^^^^^^^^^^^^^^^^^^^^^^^^^^^^^^^^^^^^
  File "/home/airflow/.local/lib/python3.12/site-packages/airflow/models/taskinstance.py", line 3005, in _run_raw_task
    return _run_raw_task(
           ^^^^^^^^^^^^^^
  File "/home/airflow/.local/lib/python3.12/site-packages/airflow/models/taskinstance.py", line 273, in _run_raw_task
    TaskInstance._execute_task_with_callbacks(
  File "/home/airflow/.local/lib/python3.12/site-packages/airflow/models/taskinstance.py", line 3159, in _execute_task_with_callbacks
    result = self._execute_task(context, task_orig)
             ^^^^^^^^^^^^^^^^^^^^^^^^^^^^^^^^^^^^^^
  File "/home/airflow/.local/lib/python3.12/site-packages/airflow/models/taskinstance.py", line 3183, in _execute_task
    return _execute_task(self, context, task_orig)
           ^^^^^^^^^^^^^^^^^^^^^^^^^^^^^^^^^^^^^^^
  File "/home/airflow/.local/lib/python3.12/site-packages/airflow/models/taskinstance.py", line 767, in _execute_task
    result = _execute_callable(context=context, **execute_callable_kwargs)
             ^^^^^^^^^^^^^^^^^^^^^^^^^^^^^^^^^^^^^^^^^^^^^^^^^^^^^^^^^^^^^
  File "/home/airflow/.local/lib/python3.12/site-packages/airflow/models/taskinstance.py", line 733, in _execute_callable
    return ExecutionCallableRunner(
           ^^^^^^^^^^^^^^^^^^^^^^^^
  File "/home/airflow/.local/lib/python3.12/site-packages/airflow/utils/operator_helpers.py", line 252, in run
    return self.func(*args, **kwargs)
           ^^^^^^^^^^^^^^^^^^^^^^^^^^
  File "/home/airflow/.local/lib/python3.12/site-packages/airflow/models/baseoperator.py", line 417, in wrapper
    return func(self, *args, **kwargs)
           ^^^^^^^^^^^^^^^^^^^^^^^^^^^
  File "/home/airflow/.local/lib/python3.12/site-packages/airflow/providers/common/sql/operators/sql.py", line 284, in execute
    output = hook.run(
             ^^^^^^^^^
  File "/home/airflow/.local/lib/python3.12/site-packages/airflow/providers/common/sql/hooks/sql.py", line 489, in run
    self._run_command(cur, sql_statement, parameters)
  File "/home/airflow/.local/lib/python3.12/site-packages/airflow/providers/common/sql/hooks/sql.py", line 549, in _run_command
    cur.execute(sql_statement)
psycopg2.errors.UniqueViolation: duplicate key value violates unique constraint "orders_pkey"
DETAIL:  Key (orderid)=(4) already exists.

[2024-11-09T21:10:56.444+0000] {local_task_job_runner.py:266} INFO - Task exited with return code 1
[2024-11-09T21:10:56.493+0000] {taskinstance.py:3895} INFO - 0 downstream tasks scheduled from follow-on schedule check
[2024-11-09T21:10:56.501+0000] {local_task_job_runner.py:245} INFO - ::endgroup::
