[2024-11-06T19:17:07.339+0000] {local_task_job_runner.py:123} INFO - ::group::Pre task execution logs
[2024-11-06T19:17:07.482+0000] {taskinstance.py:2613} INFO - Dependencies all met for dep_context=non-requeueable deps ti=<TaskInstance: dag_with_postgres_operator.create_postgres_table scheduled__2024-02-01T00:00:00+00:00 [queued]>
[2024-11-06T19:17:07.529+0000] {taskinstance.py:2613} INFO - Dependencies all met for dep_context=requeueable deps ti=<TaskInstance: dag_with_postgres_operator.create_postgres_table scheduled__2024-02-01T00:00:00+00:00 [queued]>
[2024-11-06T19:17:07.532+0000] {taskinstance.py:2866} INFO - Starting attempt 6 of 6
[2024-11-06T19:17:07.610+0000] {taskinstance.py:2889} INFO - Executing <Task(PostgresOperator): create_postgres_table> on 2024-02-01 00:00:00+00:00
[2024-11-06T19:17:07.643+0000] {warnings.py:112} WARNING - /home/***/.local/lib/python3.12/site-packages/***/task/task_runner/standard_task_runner.py:70: DeprecationWarning: This process (pid=579) is multi-threaded, use of fork() may lead to deadlocks in the child.
  pid = os.fork()

[2024-11-06T19:17:07.648+0000] {standard_task_runner.py:72} INFO - Started process 605 to run task
[2024-11-06T19:17:07.671+0000] {standard_task_runner.py:104} INFO - Running: ['***', 'tasks', 'run', 'dag_with_postgres_operator', 'create_postgres_table', 'scheduled__2024-02-01T00:00:00+00:00', '--job-id', '96', '--raw', '--subdir', 'DAGS_FOLDER/postgres.py', '--cfg-path', '/tmp/tmp4ngk1eck']
[2024-11-06T19:17:07.683+0000] {standard_task_runner.py:105} INFO - Job 96: Subtask create_postgres_table
[2024-11-06T19:17:08.018+0000] {task_command.py:467} INFO - Running <TaskInstance: dag_with_postgres_operator.create_postgres_table scheduled__2024-02-01T00:00:00+00:00 [running]> on host 4b5a50a11bce
[2024-11-06T19:17:09.429+0000] {taskinstance.py:3132} INFO - Exporting env vars: AIRFLOW_CTX_DAG_OWNER='sumit kumar' AIRFLOW_CTX_DAG_ID='dag_with_postgres_operator' AIRFLOW_CTX_TASK_ID='create_postgres_table' AIRFLOW_CTX_EXECUTION_DATE='2024-02-01T00:00:00+00:00' AIRFLOW_CTX_TRY_NUMBER='6' AIRFLOW_CTX_DAG_RUN_ID='scheduled__2024-02-01T00:00:00+00:00'
[2024-11-06T19:17:09.438+0000] {logging_mixin.py:190} INFO - Task instance is in running state
[2024-11-06T19:17:09.445+0000] {logging_mixin.py:190} INFO -  Previous state of the Task instance: queued
[2024-11-06T19:17:09.451+0000] {logging_mixin.py:190} INFO - Current task name:create_postgres_table state:running start_date:2024-11-06 19:17:07.483751+00:00
[2024-11-06T19:17:09.452+0000] {logging_mixin.py:190} INFO - Dag name:dag_with_postgres_operator and current dag run status:running
[2024-11-06T19:17:09.458+0000] {taskinstance.py:731} INFO - ::endgroup::
[2024-11-06T19:17:09.459+0000] {sql.py:278} INFO - Executing: 
            CREATE TABLE if not exists Orders (
                OrderID INT PRIMARY KEY,
                Status VARCHAR(50)
            )
        
[2024-11-06T19:17:09.620+0000] {taskinstance.py:3311} ERROR - Task failed with exception
Traceback (most recent call last):
  File "/home/airflow/.local/lib/python3.12/site-packages/airflow/models/taskinstance.py", line 767, in _execute_task
    result = _execute_callable(context=context, **execute_callable_kwargs)
             ^^^^^^^^^^^^^^^^^^^^^^^^^^^^^^^^^^^^^^^^^^^^^^^^^^^^^^^^^^^^^
  File "/home/airflow/.local/lib/python3.12/site-packages/airflow/models/taskinstance.py", line 733, in _execute_callable
    return ExecutionCallableRunner(
           ^^^^^^^^^^^^^^^^^^^^^^^^
  File "/home/airflow/.local/lib/python3.12/site-packages/airflow/utils/operator_helpers.py", line 252, in run
    return self.func(*args, **kwargs)
           ^^^^^^^^^^^^^^^^^^^^^^^^^^
  File "/home/airflow/.local/lib/python3.12/site-packages/airflow/models/baseoperator.py", line 417, in wrapper
    return func(self, *args, **kwargs)
           ^^^^^^^^^^^^^^^^^^^^^^^^^^^
  File "/home/airflow/.local/lib/python3.12/site-packages/airflow/providers/common/sql/operators/sql.py", line 279, in execute
    hook = self.get_db_hook()
           ^^^^^^^^^^^^^^^^^^
  File "/home/airflow/.local/lib/python3.12/site-packages/airflow/providers/common/sql/operators/sql.py", line 190, in get_db_hook
    return self._hook
           ^^^^^^^^^^
  File "/usr/local/lib/python3.12/functools.py", line 993, in __get__
    val = self.func(instance)
          ^^^^^^^^^^^^^^^^^^^
  File "/home/airflow/.local/lib/python3.12/site-packages/airflow/providers/common/sql/operators/sql.py", line 166, in _hook
    hook = self.get_hook(conn_id=conn_id, hook_params=self.hook_params)
           ^^^^^^^^^^^^^^^^^^^^^^^^^^^^^^^^^^^^^^^^^^^^^^^^^^^^^^^^^^^^
  File "/home/airflow/.local/lib/python3.12/site-packages/airflow/providers/common/sql/operators/sql.py", line 158, in get_hook
    connection = BaseHook.get_connection(conn_id)
                 ^^^^^^^^^^^^^^^^^^^^^^^^^^^^^^^^
  File "/home/airflow/.local/lib/python3.12/site-packages/airflow/hooks/base.py", line 83, in get_connection
    conn = Connection.get_connection_from_secrets(conn_id)
           ^^^^^^^^^^^^^^^^^^^^^^^^^^^^^^^^^^^^^^^^^^^^^^^
  File "/home/airflow/.local/lib/python3.12/site-packages/airflow/models/connection.py", line 537, in get_connection_from_secrets
    raise AirflowNotFoundException(f"The conn_id `{conn_id}` isn't defined")
airflow.exceptions.AirflowNotFoundException: The conn_id `postgres_local` isn't defined
[2024-11-06T19:17:09.683+0000] {logging_mixin.py:190} INFO - Task instance in failure state
[2024-11-06T19:17:09.684+0000] {logging_mixin.py:190} INFO - Task start:2024-11-06 19:17:07.483751+00:00 end:2024-11-06 19:17:09.682070+00:00 duration:2.198319
[2024-11-06T19:17:09.693+0000] {logging_mixin.py:190} INFO - Task:<Task(PostgresOperator): create_postgres_table> dag:<DAG: dag_with_postgres_operator> dagrun:<DagRun dag_with_postgres_operator @ 2024-02-01 00:00:00+00:00: scheduled__2024-02-01T00:00:00+00:00, state:running, queued_at: 2024-11-06 19:10:43.145954+00:00. externally triggered: False>
[2024-11-06T19:17:09.694+0000] {logging_mixin.py:190} INFO - Failure caused by The conn_id `postgres_local` isn't defined
[2024-11-06T19:17:09.695+0000] {taskinstance.py:1225} INFO - Marking task as FAILED. dag_id=dag_with_postgres_operator, task_id=create_postgres_table, run_id=scheduled__2024-02-01T00:00:00+00:00, execution_date=20240201T000000, start_date=20241106T191707, end_date=20241106T191709
[2024-11-06T19:17:09.809+0000] {taskinstance.py:340} INFO - ::group::Post task execution logs
[2024-11-06T19:17:09.815+0000] {standard_task_runner.py:124} ERROR - Failed to execute job 96 for task create_postgres_table (The conn_id `postgres_local` isn't defined; 605)
Traceback (most recent call last):
  File "/home/airflow/.local/lib/python3.12/site-packages/airflow/task/task_runner/standard_task_runner.py", line 117, in _start_by_fork
    ret = args.func(args, dag=self.dag)
          ^^^^^^^^^^^^^^^^^^^^^^^^^^^^^
  File "/home/airflow/.local/lib/python3.12/site-packages/airflow/cli/cli_config.py", line 49, in command
    return func(*args, **kwargs)
           ^^^^^^^^^^^^^^^^^^^^^
  File "/home/airflow/.local/lib/python3.12/site-packages/airflow/utils/cli.py", line 116, in wrapper
    return f(*args, **kwargs)
           ^^^^^^^^^^^^^^^^^^
  File "/home/airflow/.local/lib/python3.12/site-packages/airflow/cli/commands/task_command.py", line 483, in task_run
    task_return_code = _run_task_by_selected_method(args, _dag, ti)
                       ^^^^^^^^^^^^^^^^^^^^^^^^^^^^^^^^^^^^^^^^^^^^
  File "/home/airflow/.local/lib/python3.12/site-packages/airflow/cli/commands/task_command.py", line 256, in _run_task_by_selected_method
    return _run_raw_task(args, ti)
           ^^^^^^^^^^^^^^^^^^^^^^^
  File "/home/airflow/.local/lib/python3.12/site-packages/airflow/cli/commands/task_command.py", line 341, in _run_raw_task
    return ti._run_raw_task(
           ^^^^^^^^^^^^^^^^^
  File "/home/airflow/.local/lib/python3.12/site-packages/airflow/utils/session.py", line 97, in wrapper
    return func(*args, session=session, **kwargs)
           ^^^^^^^^^^^^^^^^^^^^^^^^^^^^^^^^^^^^^^
  File "/home/airflow/.local/lib/python3.12/site-packages/airflow/models/taskinstance.py", line 3005, in _run_raw_task
    return _run_raw_task(
           ^^^^^^^^^^^^^^
  File "/home/airflow/.local/lib/python3.12/site-packages/airflow/models/taskinstance.py", line 273, in _run_raw_task
    TaskInstance._execute_task_with_callbacks(
  File "/home/airflow/.local/lib/python3.12/site-packages/airflow/models/taskinstance.py", line 3159, in _execute_task_with_callbacks
    result = self._execute_task(context, task_orig)
             ^^^^^^^^^^^^^^^^^^^^^^^^^^^^^^^^^^^^^^
  File "/home/airflow/.local/lib/python3.12/site-packages/airflow/models/taskinstance.py", line 3183, in _execute_task
    return _execute_task(self, context, task_orig)
           ^^^^^^^^^^^^^^^^^^^^^^^^^^^^^^^^^^^^^^^
  File "/home/airflow/.local/lib/python3.12/site-packages/airflow/models/taskinstance.py", line 767, in _execute_task
    result = _execute_callable(context=context, **execute_callable_kwargs)
             ^^^^^^^^^^^^^^^^^^^^^^^^^^^^^^^^^^^^^^^^^^^^^^^^^^^^^^^^^^^^^
  File "/home/airflow/.local/lib/python3.12/site-packages/airflow/models/taskinstance.py", line 733, in _execute_callable
    return ExecutionCallableRunner(
           ^^^^^^^^^^^^^^^^^^^^^^^^
  File "/home/airflow/.local/lib/python3.12/site-packages/airflow/utils/operator_helpers.py", line 252, in run
    return self.func(*args, **kwargs)
           ^^^^^^^^^^^^^^^^^^^^^^^^^^
  File "/home/airflow/.local/lib/python3.12/site-packages/airflow/models/baseoperator.py", line 417, in wrapper
    return func(self, *args, **kwargs)
           ^^^^^^^^^^^^^^^^^^^^^^^^^^^
  File "/home/airflow/.local/lib/python3.12/site-packages/airflow/providers/common/sql/operators/sql.py", line 279, in execute
    hook = self.get_db_hook()
           ^^^^^^^^^^^^^^^^^^
  File "/home/airflow/.local/lib/python3.12/site-packages/airflow/providers/common/sql/operators/sql.py", line 190, in get_db_hook
    return self._hook
           ^^^^^^^^^^
  File "/usr/local/lib/python3.12/functools.py", line 993, in __get__
    val = self.func(instance)
          ^^^^^^^^^^^^^^^^^^^
  File "/home/airflow/.local/lib/python3.12/site-packages/airflow/providers/common/sql/operators/sql.py", line 166, in _hook
    hook = self.get_hook(conn_id=conn_id, hook_params=self.hook_params)
           ^^^^^^^^^^^^^^^^^^^^^^^^^^^^^^^^^^^^^^^^^^^^^^^^^^^^^^^^^^^^
  File "/home/airflow/.local/lib/python3.12/site-packages/airflow/providers/common/sql/operators/sql.py", line 158, in get_hook
    connection = BaseHook.get_connection(conn_id)
                 ^^^^^^^^^^^^^^^^^^^^^^^^^^^^^^^^
  File "/home/airflow/.local/lib/python3.12/site-packages/airflow/hooks/base.py", line 83, in get_connection
    conn = Connection.get_connection_from_secrets(conn_id)
           ^^^^^^^^^^^^^^^^^^^^^^^^^^^^^^^^^^^^^^^^^^^^^^^
  File "/home/airflow/.local/lib/python3.12/site-packages/airflow/models/connection.py", line 537, in get_connection_from_secrets
    raise AirflowNotFoundException(f"The conn_id `{conn_id}` isn't defined")
airflow.exceptions.AirflowNotFoundException: The conn_id `postgres_local` isn't defined
[2024-11-06T19:17:09.954+0000] {local_task_job_runner.py:266} INFO - Task exited with return code 1
[2024-11-06T19:17:09.987+0000] {local_task_job_runner.py:245} INFO - ::endgroup::
[2024-11-09T17:58:25.569+0000] {local_task_job_runner.py:123} INFO - ::group::Pre task execution logs
[2024-11-09T17:58:25.658+0000] {taskinstance.py:2613} INFO - Dependencies all met for dep_context=non-requeueable deps ti=<TaskInstance: dag_with_postgres_operator.create_postgres_table scheduled__2024-02-01T00:00:00+00:00 [queued]>
[2024-11-09T17:58:25.723+0000] {taskinstance.py:2613} INFO - Dependencies all met for dep_context=requeueable deps ti=<TaskInstance: dag_with_postgres_operator.create_postgres_table scheduled__2024-02-01T00:00:00+00:00 [queued]>
[2024-11-09T17:58:25.740+0000] {taskinstance.py:2866} INFO - Starting attempt 6 of 6
[2024-11-09T17:58:25.821+0000] {taskinstance.py:2889} INFO - Executing <Task(PostgresOperator): create_postgres_table> on 2024-02-01 00:00:00+00:00
[2024-11-09T17:58:25.843+0000] {warnings.py:112} WARNING - /home/***/.local/lib/python3.12/site-packages/***/task/task_runner/standard_task_runner.py:70: DeprecationWarning: This process (pid=522) is multi-threaded, use of fork() may lead to deadlocks in the child.
  pid = os.fork()

[2024-11-09T17:58:25.860+0000] {standard_task_runner.py:72} INFO - Started process 550 to run task
[2024-11-09T17:58:25.851+0000] {standard_task_runner.py:104} INFO - Running: ['***', 'tasks', 'run', 'dag_with_postgres_operator', 'create_postgres_table', 'scheduled__2024-02-01T00:00:00+00:00', '--job-id', '95', '--raw', '--subdir', 'DAGS_FOLDER/postgres.py', '--cfg-path', '/tmp/tmpnhzts9ac']
[2024-11-09T17:58:25.911+0000] {standard_task_runner.py:105} INFO - Job 95: Subtask create_postgres_table
[2024-11-09T17:58:26.198+0000] {task_command.py:467} INFO - Running <TaskInstance: dag_with_postgres_operator.create_postgres_table scheduled__2024-02-01T00:00:00+00:00 [running]> on host 7a581205cd28
[2024-11-09T17:58:26.821+0000] {taskinstance.py:3132} INFO - Exporting env vars: AIRFLOW_CTX_DAG_OWNER='sumit kumar' AIRFLOW_CTX_DAG_ID='dag_with_postgres_operator' AIRFLOW_CTX_TASK_ID='create_postgres_table' AIRFLOW_CTX_EXECUTION_DATE='2024-02-01T00:00:00+00:00' AIRFLOW_CTX_TRY_NUMBER='6' AIRFLOW_CTX_DAG_RUN_ID='scheduled__2024-02-01T00:00:00+00:00'
[2024-11-09T17:58:26.892+0000] {logging_mixin.py:190} INFO - Task instance is in running state
[2024-11-09T17:58:26.899+0000] {logging_mixin.py:190} INFO -  Previous state of the Task instance: queued
[2024-11-09T17:58:26.900+0000] {logging_mixin.py:190} INFO - Current task name:create_postgres_table state:running start_date:2024-11-09 17:58:25.673269+00:00
[2024-11-09T17:58:26.901+0000] {logging_mixin.py:190} INFO - Dag name:dag_with_postgres_operator and current dag run status:running
[2024-11-09T17:58:26.922+0000] {taskinstance.py:731} INFO - ::endgroup::
[2024-11-09T17:58:26.934+0000] {sql.py:278} INFO - Executing: 
            CREATE TABLE if not exists Orders (
                OrderID INT PRIMARY KEY,
                Status VARCHAR(50)
            )
        
[2024-11-09T17:58:27.030+0000] {taskinstance.py:3311} ERROR - Task failed with exception
Traceback (most recent call last):
  File "/home/airflow/.local/lib/python3.12/site-packages/airflow/models/taskinstance.py", line 767, in _execute_task
    result = _execute_callable(context=context, **execute_callable_kwargs)
             ^^^^^^^^^^^^^^^^^^^^^^^^^^^^^^^^^^^^^^^^^^^^^^^^^^^^^^^^^^^^^
  File "/home/airflow/.local/lib/python3.12/site-packages/airflow/models/taskinstance.py", line 733, in _execute_callable
    return ExecutionCallableRunner(
           ^^^^^^^^^^^^^^^^^^^^^^^^
  File "/home/airflow/.local/lib/python3.12/site-packages/airflow/utils/operator_helpers.py", line 252, in run
    return self.func(*args, **kwargs)
           ^^^^^^^^^^^^^^^^^^^^^^^^^^
  File "/home/airflow/.local/lib/python3.12/site-packages/airflow/models/baseoperator.py", line 417, in wrapper
    return func(self, *args, **kwargs)
           ^^^^^^^^^^^^^^^^^^^^^^^^^^^
  File "/home/airflow/.local/lib/python3.12/site-packages/airflow/providers/common/sql/operators/sql.py", line 279, in execute
    hook = self.get_db_hook()
           ^^^^^^^^^^^^^^^^^^
  File "/home/airflow/.local/lib/python3.12/site-packages/airflow/providers/common/sql/operators/sql.py", line 190, in get_db_hook
    return self._hook
           ^^^^^^^^^^
  File "/usr/local/lib/python3.12/functools.py", line 993, in __get__
    val = self.func(instance)
          ^^^^^^^^^^^^^^^^^^^
  File "/home/airflow/.local/lib/python3.12/site-packages/airflow/providers/common/sql/operators/sql.py", line 166, in _hook
    hook = self.get_hook(conn_id=conn_id, hook_params=self.hook_params)
           ^^^^^^^^^^^^^^^^^^^^^^^^^^^^^^^^^^^^^^^^^^^^^^^^^^^^^^^^^^^^
  File "/home/airflow/.local/lib/python3.12/site-packages/airflow/providers/common/sql/operators/sql.py", line 158, in get_hook
    connection = BaseHook.get_connection(conn_id)
                 ^^^^^^^^^^^^^^^^^^^^^^^^^^^^^^^^
  File "/home/airflow/.local/lib/python3.12/site-packages/airflow/hooks/base.py", line 83, in get_connection
    conn = Connection.get_connection_from_secrets(conn_id)
           ^^^^^^^^^^^^^^^^^^^^^^^^^^^^^^^^^^^^^^^^^^^^^^^
  File "/home/airflow/.local/lib/python3.12/site-packages/airflow/models/connection.py", line 537, in get_connection_from_secrets
    raise AirflowNotFoundException(f"The conn_id `{conn_id}` isn't defined")
airflow.exceptions.AirflowNotFoundException: The conn_id `postgres_local` isn't defined
[2024-11-09T17:58:27.082+0000] {logging_mixin.py:190} INFO - Task instance in failure state
[2024-11-09T17:58:27.089+0000] {logging_mixin.py:190} INFO - Task start:2024-11-09 17:58:25.673269+00:00 end:2024-11-09 17:58:27.081718+00:00 duration:1.408449
[2024-11-09T17:58:27.091+0000] {logging_mixin.py:190} INFO - Task:<Task(PostgresOperator): create_postgres_table> dag:<DAG: dag_with_postgres_operator> dagrun:<DagRun dag_with_postgres_operator @ 2024-02-01 00:00:00+00:00: scheduled__2024-02-01T00:00:00+00:00, state:running, queued_at: 2024-11-09 17:51:57.031072+00:00. externally triggered: False>
[2024-11-09T17:58:27.092+0000] {logging_mixin.py:190} INFO - Failure caused by The conn_id `postgres_local` isn't defined
[2024-11-09T17:58:27.109+0000] {taskinstance.py:1225} INFO - Marking task as FAILED. dag_id=dag_with_postgres_operator, task_id=create_postgres_table, run_id=scheduled__2024-02-01T00:00:00+00:00, execution_date=20240201T000000, start_date=20241109T175825, end_date=20241109T175827
[2024-11-09T17:58:27.176+0000] {taskinstance.py:340} INFO - ::group::Post task execution logs
[2024-11-09T17:58:27.181+0000] {standard_task_runner.py:124} ERROR - Failed to execute job 95 for task create_postgres_table (The conn_id `postgres_local` isn't defined; 550)
Traceback (most recent call last):
  File "/home/airflow/.local/lib/python3.12/site-packages/airflow/task/task_runner/standard_task_runner.py", line 117, in _start_by_fork
    ret = args.func(args, dag=self.dag)
          ^^^^^^^^^^^^^^^^^^^^^^^^^^^^^
  File "/home/airflow/.local/lib/python3.12/site-packages/airflow/cli/cli_config.py", line 49, in command
    return func(*args, **kwargs)
           ^^^^^^^^^^^^^^^^^^^^^
  File "/home/airflow/.local/lib/python3.12/site-packages/airflow/utils/cli.py", line 116, in wrapper
    return f(*args, **kwargs)
           ^^^^^^^^^^^^^^^^^^
  File "/home/airflow/.local/lib/python3.12/site-packages/airflow/cli/commands/task_command.py", line 483, in task_run
    task_return_code = _run_task_by_selected_method(args, _dag, ti)
                       ^^^^^^^^^^^^^^^^^^^^^^^^^^^^^^^^^^^^^^^^^^^^
  File "/home/airflow/.local/lib/python3.12/site-packages/airflow/cli/commands/task_command.py", line 256, in _run_task_by_selected_method
    return _run_raw_task(args, ti)
           ^^^^^^^^^^^^^^^^^^^^^^^
  File "/home/airflow/.local/lib/python3.12/site-packages/airflow/cli/commands/task_command.py", line 341, in _run_raw_task
    return ti._run_raw_task(
           ^^^^^^^^^^^^^^^^^
  File "/home/airflow/.local/lib/python3.12/site-packages/airflow/utils/session.py", line 97, in wrapper
    return func(*args, session=session, **kwargs)
           ^^^^^^^^^^^^^^^^^^^^^^^^^^^^^^^^^^^^^^
  File "/home/airflow/.local/lib/python3.12/site-packages/airflow/models/taskinstance.py", line 3005, in _run_raw_task
    return _run_raw_task(
           ^^^^^^^^^^^^^^
  File "/home/airflow/.local/lib/python3.12/site-packages/airflow/models/taskinstance.py", line 273, in _run_raw_task
    TaskInstance._execute_task_with_callbacks(
  File "/home/airflow/.local/lib/python3.12/site-packages/airflow/models/taskinstance.py", line 3159, in _execute_task_with_callbacks
    result = self._execute_task(context, task_orig)
             ^^^^^^^^^^^^^^^^^^^^^^^^^^^^^^^^^^^^^^
  File "/home/airflow/.local/lib/python3.12/site-packages/airflow/models/taskinstance.py", line 3183, in _execute_task
    return _execute_task(self, context, task_orig)
           ^^^^^^^^^^^^^^^^^^^^^^^^^^^^^^^^^^^^^^^
  File "/home/airflow/.local/lib/python3.12/site-packages/airflow/models/taskinstance.py", line 767, in _execute_task
    result = _execute_callable(context=context, **execute_callable_kwargs)
             ^^^^^^^^^^^^^^^^^^^^^^^^^^^^^^^^^^^^^^^^^^^^^^^^^^^^^^^^^^^^^
  File "/home/airflow/.local/lib/python3.12/site-packages/airflow/models/taskinstance.py", line 733, in _execute_callable
    return ExecutionCallableRunner(
           ^^^^^^^^^^^^^^^^^^^^^^^^
  File "/home/airflow/.local/lib/python3.12/site-packages/airflow/utils/operator_helpers.py", line 252, in run
    return self.func(*args, **kwargs)
           ^^^^^^^^^^^^^^^^^^^^^^^^^^
  File "/home/airflow/.local/lib/python3.12/site-packages/airflow/models/baseoperator.py", line 417, in wrapper
    return func(self, *args, **kwargs)
           ^^^^^^^^^^^^^^^^^^^^^^^^^^^
  File "/home/airflow/.local/lib/python3.12/site-packages/airflow/providers/common/sql/operators/sql.py", line 279, in execute
    hook = self.get_db_hook()
           ^^^^^^^^^^^^^^^^^^
  File "/home/airflow/.local/lib/python3.12/site-packages/airflow/providers/common/sql/operators/sql.py", line 190, in get_db_hook
    return self._hook
           ^^^^^^^^^^
  File "/usr/local/lib/python3.12/functools.py", line 993, in __get__
    val = self.func(instance)
          ^^^^^^^^^^^^^^^^^^^
  File "/home/airflow/.local/lib/python3.12/site-packages/airflow/providers/common/sql/operators/sql.py", line 166, in _hook
    hook = self.get_hook(conn_id=conn_id, hook_params=self.hook_params)
           ^^^^^^^^^^^^^^^^^^^^^^^^^^^^^^^^^^^^^^^^^^^^^^^^^^^^^^^^^^^^
  File "/home/airflow/.local/lib/python3.12/site-packages/airflow/providers/common/sql/operators/sql.py", line 158, in get_hook
    connection = BaseHook.get_connection(conn_id)
                 ^^^^^^^^^^^^^^^^^^^^^^^^^^^^^^^^
  File "/home/airflow/.local/lib/python3.12/site-packages/airflow/hooks/base.py", line 83, in get_connection
    conn = Connection.get_connection_from_secrets(conn_id)
           ^^^^^^^^^^^^^^^^^^^^^^^^^^^^^^^^^^^^^^^^^^^^^^^
  File "/home/airflow/.local/lib/python3.12/site-packages/airflow/models/connection.py", line 537, in get_connection_from_secrets
    raise AirflowNotFoundException(f"The conn_id `{conn_id}` isn't defined")
airflow.exceptions.AirflowNotFoundException: The conn_id `postgres_local` isn't defined
[2024-11-09T17:58:27.303+0000] {local_task_job_runner.py:266} INFO - Task exited with return code 1
[2024-11-09T17:58:27.421+0000] {taskinstance.py:3895} INFO - 0 downstream tasks scheduled from follow-on schedule check
[2024-11-09T17:58:27.452+0000] {local_task_job_runner.py:245} INFO - ::endgroup::
