[2024-11-06T21:10:00.136+0000] {local_task_job_runner.py:123} INFO - ::group::Pre task execution logs
[2024-11-06T21:10:00.170+0000] {taskinstance.py:2613} INFO - Dependencies all met for dep_context=non-requeueable deps ti=<TaskInstance: dag_with_postgres_operator.insert_into_table scheduled__2024-04-04T00:00:00+00:00 [queued]>
[2024-11-06T21:10:00.187+0000] {taskinstance.py:2613} INFO - Dependencies all met for dep_context=requeueable deps ti=<TaskInstance: dag_with_postgres_operator.insert_into_table scheduled__2024-04-04T00:00:00+00:00 [queued]>
[2024-11-06T21:10:00.188+0000] {taskinstance.py:2866} INFO - Starting attempt 1 of 6
[2024-11-06T21:10:00.229+0000] {taskinstance.py:2889} INFO - Executing <Task(PostgresOperator): insert_into_table> on 2024-04-04 00:00:00+00:00
[2024-11-06T21:10:00.248+0000] {warnings.py:112} WARNING - /home/***/.local/lib/python3.12/site-packages/***/task/task_runner/standard_task_runner.py:70: DeprecationWarning: This process (pid=2478) is multi-threaded, use of fork() may lead to deadlocks in the child.
  pid = os.fork()

[2024-11-06T21:10:00.250+0000] {standard_task_runner.py:72} INFO - Started process 2493 to run task
[2024-11-06T21:10:00.251+0000] {standard_task_runner.py:104} INFO - Running: ['***', 'tasks', 'run', 'dag_with_postgres_operator', 'insert_into_table', 'scheduled__2024-04-04T00:00:00+00:00', '--job-id', '480', '--raw', '--subdir', 'DAGS_FOLDER/postgres.py', '--cfg-path', '/tmp/tmpxbrg65g_']
[2024-11-06T21:10:00.255+0000] {standard_task_runner.py:105} INFO - Job 480: Subtask insert_into_table
[2024-11-06T21:10:00.342+0000] {task_command.py:467} INFO - Running <TaskInstance: dag_with_postgres_operator.insert_into_table scheduled__2024-04-04T00:00:00+00:00 [running]> on host 3f85553e814e
[2024-11-06T21:10:00.801+0000] {taskinstance.py:3132} INFO - Exporting env vars: AIRFLOW_CTX_DAG_OWNER='sumit kumar' AIRFLOW_CTX_DAG_ID='dag_with_postgres_operator' AIRFLOW_CTX_TASK_ID='insert_into_table' AIRFLOW_CTX_EXECUTION_DATE='2024-04-04T00:00:00+00:00' AIRFLOW_CTX_TRY_NUMBER='1' AIRFLOW_CTX_DAG_RUN_ID='scheduled__2024-04-04T00:00:00+00:00'
[2024-11-06T21:10:00.802+0000] {logging_mixin.py:190} INFO - Task instance is in running state
[2024-11-06T21:10:00.803+0000] {logging_mixin.py:190} INFO -  Previous state of the Task instance: queued
[2024-11-06T21:10:00.804+0000] {logging_mixin.py:190} INFO - Current task name:insert_into_table state:running start_date:2024-11-06 21:10:00.171497+00:00
[2024-11-06T21:10:00.805+0000] {logging_mixin.py:190} INFO - Dag name:dag_with_postgres_operator and current dag run status:running
[2024-11-06T21:10:00.806+0000] {taskinstance.py:731} INFO - ::endgroup::
[2024-11-06T21:10:00.807+0000] {sql.py:278} INFO - Executing: 
            insert into Orders values(4,'No delivired')
        
[2024-11-06T21:10:00.824+0000] {base.py:84} INFO - Retrieving connection 'postgres_local'
[2024-11-06T21:10:00.840+0000] {base.py:84} INFO - Retrieving connection 'postgres_local'
[2024-11-06T21:10:00.856+0000] {sql.py:544} INFO - Running statement: 
            insert into Orders values(4,'No delivired')
        , parameters: None
[2024-11-06T21:10:00.865+0000] {taskinstance.py:3311} ERROR - Task failed with exception
Traceback (most recent call last):
  File "/home/airflow/.local/lib/python3.12/site-packages/airflow/models/taskinstance.py", line 767, in _execute_task
    result = _execute_callable(context=context, **execute_callable_kwargs)
             ^^^^^^^^^^^^^^^^^^^^^^^^^^^^^^^^^^^^^^^^^^^^^^^^^^^^^^^^^^^^^
  File "/home/airflow/.local/lib/python3.12/site-packages/airflow/models/taskinstance.py", line 733, in _execute_callable
    return ExecutionCallableRunner(
           ^^^^^^^^^^^^^^^^^^^^^^^^
  File "/home/airflow/.local/lib/python3.12/site-packages/airflow/utils/operator_helpers.py", line 252, in run
    return self.func(*args, **kwargs)
           ^^^^^^^^^^^^^^^^^^^^^^^^^^
  File "/home/airflow/.local/lib/python3.12/site-packages/airflow/models/baseoperator.py", line 417, in wrapper
    return func(self, *args, **kwargs)
           ^^^^^^^^^^^^^^^^^^^^^^^^^^^
  File "/home/airflow/.local/lib/python3.12/site-packages/airflow/providers/common/sql/operators/sql.py", line 284, in execute
    output = hook.run(
             ^^^^^^^^^
  File "/home/airflow/.local/lib/python3.12/site-packages/airflow/providers/common/sql/hooks/sql.py", line 489, in run
    self._run_command(cur, sql_statement, parameters)
  File "/home/airflow/.local/lib/python3.12/site-packages/airflow/providers/common/sql/hooks/sql.py", line 549, in _run_command
    cur.execute(sql_statement)
psycopg2.errors.UniqueViolation: duplicate key value violates unique constraint "orders_pkey"
DETAIL:  Key (orderid)=(4) already exists.

[2024-11-06T21:10:00.887+0000] {logging_mixin.py:190} INFO - Task instance in failure state
[2024-11-06T21:10:00.887+0000] {logging_mixin.py:190} INFO - Task start:2024-11-06 21:10:00.171497+00:00 end:2024-11-06 21:10:00.886614+00:00 duration:0.715117
[2024-11-06T21:10:00.888+0000] {logging_mixin.py:190} INFO - Task:<Task(PostgresOperator): insert_into_table> dag:<DAG: dag_with_postgres_operator> dagrun:<DagRun dag_with_postgres_operator @ 2024-04-04 00:00:00+00:00: scheduled__2024-04-04T00:00:00+00:00, state:running, queued_at: 2024-11-06 21:09:52.667499+00:00. externally triggered: False>
[2024-11-06T21:10:00.888+0000] {logging_mixin.py:190} INFO - Failure caused by duplicate key value violates unique constraint "orders_pkey"
DETAIL:  Key (orderid)=(4) already exists.
[2024-11-06T21:10:00.889+0000] {taskinstance.py:1225} INFO - Marking task as UP_FOR_RETRY. dag_id=dag_with_postgres_operator, task_id=insert_into_table, run_id=scheduled__2024-04-04T00:00:00+00:00, execution_date=20240404T000000, start_date=20241106T211000, end_date=20241106T211000
[2024-11-06T21:10:00.915+0000] {taskinstance.py:340} INFO - ::group::Post task execution logs
[2024-11-06T21:10:00.916+0000] {standard_task_runner.py:124} ERROR - Failed to execute job 480 for task insert_into_table (duplicate key value violates unique constraint "orders_pkey"
DETAIL:  Key (orderid)=(4) already exists.
; 2493)
Traceback (most recent call last):
  File "/home/airflow/.local/lib/python3.12/site-packages/airflow/task/task_runner/standard_task_runner.py", line 117, in _start_by_fork
    ret = args.func(args, dag=self.dag)
          ^^^^^^^^^^^^^^^^^^^^^^^^^^^^^
  File "/home/airflow/.local/lib/python3.12/site-packages/airflow/cli/cli_config.py", line 49, in command
    return func(*args, **kwargs)
           ^^^^^^^^^^^^^^^^^^^^^
  File "/home/airflow/.local/lib/python3.12/site-packages/airflow/utils/cli.py", line 116, in wrapper
    return f(*args, **kwargs)
           ^^^^^^^^^^^^^^^^^^
  File "/home/airflow/.local/lib/python3.12/site-packages/airflow/cli/commands/task_command.py", line 483, in task_run
    task_return_code = _run_task_by_selected_method(args, _dag, ti)
                       ^^^^^^^^^^^^^^^^^^^^^^^^^^^^^^^^^^^^^^^^^^^^
  File "/home/airflow/.local/lib/python3.12/site-packages/airflow/cli/commands/task_command.py", line 256, in _run_task_by_selected_method
    return _run_raw_task(args, ti)
           ^^^^^^^^^^^^^^^^^^^^^^^
  File "/home/airflow/.local/lib/python3.12/site-packages/airflow/cli/commands/task_command.py", line 341, in _run_raw_task
    return ti._run_raw_task(
           ^^^^^^^^^^^^^^^^^
  File "/home/airflow/.local/lib/python3.12/site-packages/airflow/utils/session.py", line 97, in wrapper
    return func(*args, session=session, **kwargs)
           ^^^^^^^^^^^^^^^^^^^^^^^^^^^^^^^^^^^^^^
  File "/home/airflow/.local/lib/python3.12/site-packages/airflow/models/taskinstance.py", line 3005, in _run_raw_task
    return _run_raw_task(
           ^^^^^^^^^^^^^^
  File "/home/airflow/.local/lib/python3.12/site-packages/airflow/models/taskinstance.py", line 273, in _run_raw_task
    TaskInstance._execute_task_with_callbacks(
  File "/home/airflow/.local/lib/python3.12/site-packages/airflow/models/taskinstance.py", line 3159, in _execute_task_with_callbacks
    result = self._execute_task(context, task_orig)
             ^^^^^^^^^^^^^^^^^^^^^^^^^^^^^^^^^^^^^^
  File "/home/airflow/.local/lib/python3.12/site-packages/airflow/models/taskinstance.py", line 3183, in _execute_task
    return _execute_task(self, context, task_orig)
           ^^^^^^^^^^^^^^^^^^^^^^^^^^^^^^^^^^^^^^^
  File "/home/airflow/.local/lib/python3.12/site-packages/airflow/models/taskinstance.py", line 767, in _execute_task
    result = _execute_callable(context=context, **execute_callable_kwargs)
             ^^^^^^^^^^^^^^^^^^^^^^^^^^^^^^^^^^^^^^^^^^^^^^^^^^^^^^^^^^^^^
  File "/home/airflow/.local/lib/python3.12/site-packages/airflow/models/taskinstance.py", line 733, in _execute_callable
    return ExecutionCallableRunner(
           ^^^^^^^^^^^^^^^^^^^^^^^^
  File "/home/airflow/.local/lib/python3.12/site-packages/airflow/utils/operator_helpers.py", line 252, in run
    return self.func(*args, **kwargs)
           ^^^^^^^^^^^^^^^^^^^^^^^^^^
  File "/home/airflow/.local/lib/python3.12/site-packages/airflow/models/baseoperator.py", line 417, in wrapper
    return func(self, *args, **kwargs)
           ^^^^^^^^^^^^^^^^^^^^^^^^^^^
  File "/home/airflow/.local/lib/python3.12/site-packages/airflow/providers/common/sql/operators/sql.py", line 284, in execute
    output = hook.run(
             ^^^^^^^^^
  File "/home/airflow/.local/lib/python3.12/site-packages/airflow/providers/common/sql/hooks/sql.py", line 489, in run
    self._run_command(cur, sql_statement, parameters)
  File "/home/airflow/.local/lib/python3.12/site-packages/airflow/providers/common/sql/hooks/sql.py", line 549, in _run_command
    cur.execute(sql_statement)
psycopg2.errors.UniqueViolation: duplicate key value violates unique constraint "orders_pkey"
DETAIL:  Key (orderid)=(4) already exists.

[2024-11-06T21:10:00.948+0000] {local_task_job_runner.py:266} INFO - Task exited with return code 1
[2024-11-06T21:10:00.987+0000] {taskinstance.py:3895} INFO - 0 downstream tasks scheduled from follow-on schedule check
[2024-11-06T21:10:00.990+0000] {local_task_job_runner.py:245} INFO - ::endgroup::
[2024-11-09T20:33:37.711+0000] {local_task_job_runner.py:123} INFO - ::group::Pre task execution logs
[2024-11-09T20:33:37.980+0000] {taskinstance.py:2613} INFO - Dependencies all met for dep_context=non-requeueable deps ti=<TaskInstance: dag_with_postgres_operator.insert_into_table scheduled__2024-04-04T00:00:00+00:00 [queued]>
[2024-11-09T20:33:38.115+0000] {taskinstance.py:2613} INFO - Dependencies all met for dep_context=requeueable deps ti=<TaskInstance: dag_with_postgres_operator.insert_into_table scheduled__2024-04-04T00:00:00+00:00 [queued]>
[2024-11-09T20:33:38.118+0000] {taskinstance.py:2866} INFO - Starting attempt 1 of 6
[2024-11-09T20:33:38.307+0000] {taskinstance.py:2889} INFO - Executing <Task(PostgresOperator): insert_into_table> on 2024-04-04 00:00:00+00:00
[2024-11-09T20:33:38.348+0000] {warnings.py:112} WARNING - /home/***/.local/lib/python3.12/site-packages/***/task/task_runner/standard_task_runner.py:70: DeprecationWarning: This process (pid=1623) is multi-threaded, use of fork() may lead to deadlocks in the child.
  pid = os.fork()

[2024-11-09T20:33:38.354+0000] {standard_task_runner.py:72} INFO - Started process 1646 to run task
[2024-11-09T20:33:38.351+0000] {standard_task_runner.py:104} INFO - Running: ['***', 'tasks', 'run', 'dag_with_postgres_operator', 'insert_into_table', 'scheduled__2024-04-04T00:00:00+00:00', '--job-id', '449', '--raw', '--subdir', 'DAGS_FOLDER/postgres.py', '--cfg-path', '/tmp/tmp45mso4m7']
[2024-11-09T20:33:38.399+0000] {standard_task_runner.py:105} INFO - Job 449: Subtask insert_into_table
[2024-11-09T20:33:38.818+0000] {task_command.py:467} INFO - Running <TaskInstance: dag_with_postgres_operator.insert_into_table scheduled__2024-04-04T00:00:00+00:00 [running]> on host 7a581205cd28
[2024-11-09T20:33:39.474+0000] {taskinstance.py:3132} INFO - Exporting env vars: AIRFLOW_CTX_DAG_OWNER='sumit kumar' AIRFLOW_CTX_DAG_ID='dag_with_postgres_operator' AIRFLOW_CTX_TASK_ID='insert_into_table' AIRFLOW_CTX_EXECUTION_DATE='2024-04-04T00:00:00+00:00' AIRFLOW_CTX_TRY_NUMBER='1' AIRFLOW_CTX_DAG_RUN_ID='scheduled__2024-04-04T00:00:00+00:00'
[2024-11-09T20:33:39.478+0000] {logging_mixin.py:190} INFO - Task instance is in running state
[2024-11-09T20:33:39.479+0000] {logging_mixin.py:190} INFO -  Previous state of the Task instance: queued
[2024-11-09T20:33:39.480+0000] {logging_mixin.py:190} INFO - Current task name:insert_into_table state:running start_date:2024-11-09 20:33:37.983405+00:00
[2024-11-09T20:33:39.483+0000] {logging_mixin.py:190} INFO - Dag name:dag_with_postgres_operator and current dag run status:running
[2024-11-09T20:33:39.484+0000] {taskinstance.py:731} INFO - ::endgroup::
[2024-11-09T20:33:39.485+0000] {sql.py:278} INFO - Executing: 
            insert into Orders values(4,'No delivired')
        
[2024-11-09T20:33:39.547+0000] {base.py:84} INFO - Retrieving connection 'postgres_local'
[2024-11-09T20:33:39.577+0000] {base.py:84} INFO - Retrieving connection 'postgres_local'
[2024-11-09T20:33:39.613+0000] {sql.py:544} INFO - Running statement: 
            insert into Orders values(4,'No delivired')
        , parameters: None
[2024-11-09T20:33:39.627+0000] {taskinstance.py:3311} ERROR - Task failed with exception
Traceback (most recent call last):
  File "/home/airflow/.local/lib/python3.12/site-packages/airflow/models/taskinstance.py", line 767, in _execute_task
    result = _execute_callable(context=context, **execute_callable_kwargs)
             ^^^^^^^^^^^^^^^^^^^^^^^^^^^^^^^^^^^^^^^^^^^^^^^^^^^^^^^^^^^^^
  File "/home/airflow/.local/lib/python3.12/site-packages/airflow/models/taskinstance.py", line 733, in _execute_callable
    return ExecutionCallableRunner(
           ^^^^^^^^^^^^^^^^^^^^^^^^
  File "/home/airflow/.local/lib/python3.12/site-packages/airflow/utils/operator_helpers.py", line 252, in run
    return self.func(*args, **kwargs)
           ^^^^^^^^^^^^^^^^^^^^^^^^^^
  File "/home/airflow/.local/lib/python3.12/site-packages/airflow/models/baseoperator.py", line 417, in wrapper
    return func(self, *args, **kwargs)
           ^^^^^^^^^^^^^^^^^^^^^^^^^^^
  File "/home/airflow/.local/lib/python3.12/site-packages/airflow/providers/common/sql/operators/sql.py", line 284, in execute
    output = hook.run(
             ^^^^^^^^^
  File "/home/airflow/.local/lib/python3.12/site-packages/airflow/providers/common/sql/hooks/sql.py", line 489, in run
    self._run_command(cur, sql_statement, parameters)
  File "/home/airflow/.local/lib/python3.12/site-packages/airflow/providers/common/sql/hooks/sql.py", line 549, in _run_command
    cur.execute(sql_statement)
psycopg2.errors.UniqueViolation: duplicate key value violates unique constraint "orders_pkey"
DETAIL:  Key (orderid)=(4) already exists.

[2024-11-09T20:33:39.735+0000] {logging_mixin.py:190} INFO - Task instance in failure state
[2024-11-09T20:33:39.752+0000] {logging_mixin.py:190} INFO - Task start:2024-11-09 20:33:37.983405+00:00 end:2024-11-09 20:33:39.733711+00:00 duration:1.750306
[2024-11-09T20:33:39.762+0000] {logging_mixin.py:190} INFO - Task:<Task(PostgresOperator): insert_into_table> dag:<DAG: dag_with_postgres_operator> dagrun:<DagRun dag_with_postgres_operator @ 2024-04-04 00:00:00+00:00: scheduled__2024-04-04T00:00:00+00:00, state:running, queued_at: 2024-11-09 20:30:26.557531+00:00. externally triggered: False>
[2024-11-09T20:33:39.763+0000] {logging_mixin.py:190} INFO - Failure caused by duplicate key value violates unique constraint "orders_pkey"
DETAIL:  Key (orderid)=(4) already exists.
[2024-11-09T20:33:39.767+0000] {taskinstance.py:1225} INFO - Marking task as UP_FOR_RETRY. dag_id=dag_with_postgres_operator, task_id=insert_into_table, run_id=scheduled__2024-04-04T00:00:00+00:00, execution_date=20240404T000000, start_date=20241109T203337, end_date=20241109T203339
[2024-11-09T20:33:39.869+0000] {taskinstance.py:340} INFO - ::group::Post task execution logs
[2024-11-09T20:33:39.877+0000] {standard_task_runner.py:124} ERROR - Failed to execute job 449 for task insert_into_table (duplicate key value violates unique constraint "orders_pkey"
DETAIL:  Key (orderid)=(4) already exists.
; 1646)
Traceback (most recent call last):
  File "/home/airflow/.local/lib/python3.12/site-packages/airflow/task/task_runner/standard_task_runner.py", line 117, in _start_by_fork
    ret = args.func(args, dag=self.dag)
          ^^^^^^^^^^^^^^^^^^^^^^^^^^^^^
  File "/home/airflow/.local/lib/python3.12/site-packages/airflow/cli/cli_config.py", line 49, in command
    return func(*args, **kwargs)
           ^^^^^^^^^^^^^^^^^^^^^
  File "/home/airflow/.local/lib/python3.12/site-packages/airflow/utils/cli.py", line 116, in wrapper
    return f(*args, **kwargs)
           ^^^^^^^^^^^^^^^^^^
  File "/home/airflow/.local/lib/python3.12/site-packages/airflow/cli/commands/task_command.py", line 483, in task_run
    task_return_code = _run_task_by_selected_method(args, _dag, ti)
                       ^^^^^^^^^^^^^^^^^^^^^^^^^^^^^^^^^^^^^^^^^^^^
  File "/home/airflow/.local/lib/python3.12/site-packages/airflow/cli/commands/task_command.py", line 256, in _run_task_by_selected_method
    return _run_raw_task(args, ti)
           ^^^^^^^^^^^^^^^^^^^^^^^
  File "/home/airflow/.local/lib/python3.12/site-packages/airflow/cli/commands/task_command.py", line 341, in _run_raw_task
    return ti._run_raw_task(
           ^^^^^^^^^^^^^^^^^
  File "/home/airflow/.local/lib/python3.12/site-packages/airflow/utils/session.py", line 97, in wrapper
    return func(*args, session=session, **kwargs)
           ^^^^^^^^^^^^^^^^^^^^^^^^^^^^^^^^^^^^^^
  File "/home/airflow/.local/lib/python3.12/site-packages/airflow/models/taskinstance.py", line 3005, in _run_raw_task
    return _run_raw_task(
           ^^^^^^^^^^^^^^
  File "/home/airflow/.local/lib/python3.12/site-packages/airflow/models/taskinstance.py", line 273, in _run_raw_task
    TaskInstance._execute_task_with_callbacks(
  File "/home/airflow/.local/lib/python3.12/site-packages/airflow/models/taskinstance.py", line 3159, in _execute_task_with_callbacks
    result = self._execute_task(context, task_orig)
             ^^^^^^^^^^^^^^^^^^^^^^^^^^^^^^^^^^^^^^
  File "/home/airflow/.local/lib/python3.12/site-packages/airflow/models/taskinstance.py", line 3183, in _execute_task
    return _execute_task(self, context, task_orig)
           ^^^^^^^^^^^^^^^^^^^^^^^^^^^^^^^^^^^^^^^
  File "/home/airflow/.local/lib/python3.12/site-packages/airflow/models/taskinstance.py", line 767, in _execute_task
    result = _execute_callable(context=context, **execute_callable_kwargs)
             ^^^^^^^^^^^^^^^^^^^^^^^^^^^^^^^^^^^^^^^^^^^^^^^^^^^^^^^^^^^^^
  File "/home/airflow/.local/lib/python3.12/site-packages/airflow/models/taskinstance.py", line 733, in _execute_callable
    return ExecutionCallableRunner(
           ^^^^^^^^^^^^^^^^^^^^^^^^
  File "/home/airflow/.local/lib/python3.12/site-packages/airflow/utils/operator_helpers.py", line 252, in run
    return self.func(*args, **kwargs)
           ^^^^^^^^^^^^^^^^^^^^^^^^^^
  File "/home/airflow/.local/lib/python3.12/site-packages/airflow/models/baseoperator.py", line 417, in wrapper
    return func(self, *args, **kwargs)
           ^^^^^^^^^^^^^^^^^^^^^^^^^^^
  File "/home/airflow/.local/lib/python3.12/site-packages/airflow/providers/common/sql/operators/sql.py", line 284, in execute
    output = hook.run(
             ^^^^^^^^^
  File "/home/airflow/.local/lib/python3.12/site-packages/airflow/providers/common/sql/hooks/sql.py", line 489, in run
    self._run_command(cur, sql_statement, parameters)
  File "/home/airflow/.local/lib/python3.12/site-packages/airflow/providers/common/sql/hooks/sql.py", line 549, in _run_command
    cur.execute(sql_statement)
psycopg2.errors.UniqueViolation: duplicate key value violates unique constraint "orders_pkey"
DETAIL:  Key (orderid)=(4) already exists.

[2024-11-09T20:33:39.979+0000] {local_task_job_runner.py:266} INFO - Task exited with return code 1
[2024-11-09T20:33:40.143+0000] {taskinstance.py:3895} INFO - 0 downstream tasks scheduled from follow-on schedule check
[2024-11-09T20:33:40.150+0000] {local_task_job_runner.py:245} INFO - ::endgroup::
