[2024-11-07T20:52:20.025+0000] {local_task_job_runner.py:123} INFO - ::group::Pre task execution logs
[2024-11-07T20:52:20.065+0000] {taskinstance.py:2613} INFO - Dependencies all met for dep_context=non-requeueable deps ti=<TaskInstance: dag_with_postgres_operator.insert_into_table scheduled__2024-08-29T00:00:00+00:00 [queued]>
[2024-11-07T20:52:20.084+0000] {taskinstance.py:2613} INFO - Dependencies all met for dep_context=requeueable deps ti=<TaskInstance: dag_with_postgres_operator.insert_into_table scheduled__2024-08-29T00:00:00+00:00 [queued]>
[2024-11-07T20:52:20.085+0000] {taskinstance.py:2866} INFO - Starting attempt 2 of 6
[2024-11-07T20:52:20.116+0000] {taskinstance.py:2889} INFO - Executing <Task(PostgresOperator): insert_into_table> on 2024-08-29 00:00:00+00:00
[2024-11-07T20:52:20.127+0000] {warnings.py:112} WARNING - /home/***/.local/lib/python3.12/site-packages/***/task/task_runner/standard_task_runner.py:70: DeprecationWarning: This process (pid=4263) is multi-threaded, use of fork() may lead to deadlocks in the child.
  pid = os.fork()

[2024-11-07T20:52:20.131+0000] {standard_task_runner.py:72} INFO - Started process 4276 to run task
[2024-11-07T20:52:20.131+0000] {standard_task_runner.py:104} INFO - Running: ['***', 'tasks', 'run', 'dag_with_postgres_operator', 'insert_into_table', 'scheduled__2024-08-29T00:00:00+00:00', '--job-id', '1515', '--raw', '--subdir', 'DAGS_FOLDER/postgres.py', '--cfg-path', '/tmp/tmpaz65j5v1']
[2024-11-07T20:52:20.134+0000] {standard_task_runner.py:105} INFO - Job 1515: Subtask insert_into_table
[2024-11-07T20:52:20.251+0000] {task_command.py:467} INFO - Running <TaskInstance: dag_with_postgres_operator.insert_into_table scheduled__2024-08-29T00:00:00+00:00 [running]> on host 3f85553e814e
[2024-11-07T20:52:21.227+0000] {taskinstance.py:3132} INFO - Exporting env vars: AIRFLOW_CTX_DAG_OWNER='sumit kumar' AIRFLOW_CTX_DAG_ID='dag_with_postgres_operator' AIRFLOW_CTX_TASK_ID='insert_into_table' AIRFLOW_CTX_EXECUTION_DATE='2024-08-29T00:00:00+00:00' AIRFLOW_CTX_TRY_NUMBER='2' AIRFLOW_CTX_DAG_RUN_ID='scheduled__2024-08-29T00:00:00+00:00'
[2024-11-07T20:52:21.239+0000] {logging_mixin.py:190} INFO - Task instance is in running state
[2024-11-07T20:52:21.250+0000] {logging_mixin.py:190} INFO -  Previous state of the Task instance: queued
[2024-11-07T20:52:21.255+0000] {logging_mixin.py:190} INFO - Current task name:insert_into_table state:running start_date:2024-11-07 20:52:20.066121+00:00
[2024-11-07T20:52:21.256+0000] {logging_mixin.py:190} INFO - Dag name:dag_with_postgres_operator and current dag run status:running
[2024-11-07T20:52:21.258+0000] {taskinstance.py:731} INFO - ::endgroup::
[2024-11-07T20:52:21.260+0000] {sql.py:278} INFO - Executing: 
            insert into Orders values(4,'No delivired')
        
[2024-11-07T20:52:21.297+0000] {base.py:84} INFO - Retrieving connection 'postgres_local'
[2024-11-07T20:52:21.340+0000] {base.py:84} INFO - Retrieving connection 'postgres_local'
[2024-11-07T20:52:21.434+0000] {sql.py:544} INFO - Running statement: 
            insert into Orders values(4,'No delivired')
        , parameters: None
[2024-11-07T20:52:21.455+0000] {taskinstance.py:3311} ERROR - Task failed with exception
Traceback (most recent call last):
  File "/home/airflow/.local/lib/python3.12/site-packages/airflow/models/taskinstance.py", line 767, in _execute_task
    result = _execute_callable(context=context, **execute_callable_kwargs)
             ^^^^^^^^^^^^^^^^^^^^^^^^^^^^^^^^^^^^^^^^^^^^^^^^^^^^^^^^^^^^^
  File "/home/airflow/.local/lib/python3.12/site-packages/airflow/models/taskinstance.py", line 733, in _execute_callable
    return ExecutionCallableRunner(
           ^^^^^^^^^^^^^^^^^^^^^^^^
  File "/home/airflow/.local/lib/python3.12/site-packages/airflow/utils/operator_helpers.py", line 252, in run
    return self.func(*args, **kwargs)
           ^^^^^^^^^^^^^^^^^^^^^^^^^^
  File "/home/airflow/.local/lib/python3.12/site-packages/airflow/models/baseoperator.py", line 417, in wrapper
    return func(self, *args, **kwargs)
           ^^^^^^^^^^^^^^^^^^^^^^^^^^^
  File "/home/airflow/.local/lib/python3.12/site-packages/airflow/providers/common/sql/operators/sql.py", line 284, in execute
    output = hook.run(
             ^^^^^^^^^
  File "/home/airflow/.local/lib/python3.12/site-packages/airflow/providers/common/sql/hooks/sql.py", line 489, in run
    self._run_command(cur, sql_statement, parameters)
  File "/home/airflow/.local/lib/python3.12/site-packages/airflow/providers/common/sql/hooks/sql.py", line 549, in _run_command
    cur.execute(sql_statement)
psycopg2.errors.UniqueViolation: duplicate key value violates unique constraint "orders_pkey"
DETAIL:  Key (orderid)=(4) already exists.

[2024-11-07T20:52:21.520+0000] {logging_mixin.py:190} INFO - Task instance in failure state
[2024-11-07T20:52:21.522+0000] {logging_mixin.py:190} INFO - Task start:2024-11-07 20:52:20.066121+00:00 end:2024-11-07 20:52:21.519464+00:00 duration:1.453343
[2024-11-07T20:52:21.523+0000] {logging_mixin.py:190} INFO - Task:<Task(PostgresOperator): insert_into_table> dag:<DAG: dag_with_postgres_operator> dagrun:<DagRun dag_with_postgres_operator @ 2024-08-29 00:00:00+00:00: scheduled__2024-08-29T00:00:00+00:00, state:running, queued_at: 2024-11-07 20:50:58.553411+00:00. externally triggered: False>
[2024-11-07T20:52:21.525+0000] {logging_mixin.py:190} INFO - Failure caused by duplicate key value violates unique constraint "orders_pkey"
DETAIL:  Key (orderid)=(4) already exists.
[2024-11-07T20:52:21.528+0000] {taskinstance.py:1225} INFO - Marking task as UP_FOR_RETRY. dag_id=dag_with_postgres_operator, task_id=insert_into_table, run_id=scheduled__2024-08-29T00:00:00+00:00, execution_date=20240829T000000, start_date=20241107T205220, end_date=20241107T205221
[2024-11-07T20:52:21.767+0000] {taskinstance.py:340} INFO - ::group::Post task execution logs
[2024-11-07T20:52:21.772+0000] {standard_task_runner.py:124} ERROR - Failed to execute job 1515 for task insert_into_table (duplicate key value violates unique constraint "orders_pkey"
DETAIL:  Key (orderid)=(4) already exists.
; 4276)
Traceback (most recent call last):
  File "/home/airflow/.local/lib/python3.12/site-packages/airflow/task/task_runner/standard_task_runner.py", line 117, in _start_by_fork
    ret = args.func(args, dag=self.dag)
          ^^^^^^^^^^^^^^^^^^^^^^^^^^^^^
  File "/home/airflow/.local/lib/python3.12/site-packages/airflow/cli/cli_config.py", line 49, in command
    return func(*args, **kwargs)
           ^^^^^^^^^^^^^^^^^^^^^
  File "/home/airflow/.local/lib/python3.12/site-packages/airflow/utils/cli.py", line 116, in wrapper
    return f(*args, **kwargs)
           ^^^^^^^^^^^^^^^^^^
  File "/home/airflow/.local/lib/python3.12/site-packages/airflow/cli/commands/task_command.py", line 483, in task_run
    task_return_code = _run_task_by_selected_method(args, _dag, ti)
                       ^^^^^^^^^^^^^^^^^^^^^^^^^^^^^^^^^^^^^^^^^^^^
  File "/home/airflow/.local/lib/python3.12/site-packages/airflow/cli/commands/task_command.py", line 256, in _run_task_by_selected_method
    return _run_raw_task(args, ti)
           ^^^^^^^^^^^^^^^^^^^^^^^
  File "/home/airflow/.local/lib/python3.12/site-packages/airflow/cli/commands/task_command.py", line 341, in _run_raw_task
    return ti._run_raw_task(
           ^^^^^^^^^^^^^^^^^
  File "/home/airflow/.local/lib/python3.12/site-packages/airflow/utils/session.py", line 97, in wrapper
    return func(*args, session=session, **kwargs)
           ^^^^^^^^^^^^^^^^^^^^^^^^^^^^^^^^^^^^^^
  File "/home/airflow/.local/lib/python3.12/site-packages/airflow/models/taskinstance.py", line 3005, in _run_raw_task
    return _run_raw_task(
           ^^^^^^^^^^^^^^
  File "/home/airflow/.local/lib/python3.12/site-packages/airflow/models/taskinstance.py", line 273, in _run_raw_task
    TaskInstance._execute_task_with_callbacks(
  File "/home/airflow/.local/lib/python3.12/site-packages/airflow/models/taskinstance.py", line 3159, in _execute_task_with_callbacks
    result = self._execute_task(context, task_orig)
             ^^^^^^^^^^^^^^^^^^^^^^^^^^^^^^^^^^^^^^
  File "/home/airflow/.local/lib/python3.12/site-packages/airflow/models/taskinstance.py", line 3183, in _execute_task
    return _execute_task(self, context, task_orig)
           ^^^^^^^^^^^^^^^^^^^^^^^^^^^^^^^^^^^^^^^
  File "/home/airflow/.local/lib/python3.12/site-packages/airflow/models/taskinstance.py", line 767, in _execute_task
    result = _execute_callable(context=context, **execute_callable_kwargs)
             ^^^^^^^^^^^^^^^^^^^^^^^^^^^^^^^^^^^^^^^^^^^^^^^^^^^^^^^^^^^^^
  File "/home/airflow/.local/lib/python3.12/site-packages/airflow/models/taskinstance.py", line 733, in _execute_callable
    return ExecutionCallableRunner(
           ^^^^^^^^^^^^^^^^^^^^^^^^
  File "/home/airflow/.local/lib/python3.12/site-packages/airflow/utils/operator_helpers.py", line 252, in run
    return self.func(*args, **kwargs)
           ^^^^^^^^^^^^^^^^^^^^^^^^^^
  File "/home/airflow/.local/lib/python3.12/site-packages/airflow/models/baseoperator.py", line 417, in wrapper
    return func(self, *args, **kwargs)
           ^^^^^^^^^^^^^^^^^^^^^^^^^^^
  File "/home/airflow/.local/lib/python3.12/site-packages/airflow/providers/common/sql/operators/sql.py", line 284, in execute
    output = hook.run(
             ^^^^^^^^^
  File "/home/airflow/.local/lib/python3.12/site-packages/airflow/providers/common/sql/hooks/sql.py", line 489, in run
    self._run_command(cur, sql_statement, parameters)
  File "/home/airflow/.local/lib/python3.12/site-packages/airflow/providers/common/sql/hooks/sql.py", line 549, in _run_command
    cur.execute(sql_statement)
psycopg2.errors.UniqueViolation: duplicate key value violates unique constraint "orders_pkey"
DETAIL:  Key (orderid)=(4) already exists.

[2024-11-07T20:52:21.875+0000] {local_task_job_runner.py:266} INFO - Task exited with return code 1
[2024-11-07T20:52:21.996+0000] {taskinstance.py:3895} INFO - 0 downstream tasks scheduled from follow-on schedule check
[2024-11-07T20:52:22.015+0000] {local_task_job_runner.py:245} INFO - ::endgroup::
[2024-11-09T21:46:59.122+0000] {local_task_job_runner.py:123} INFO - ::group::Pre task execution logs
[2024-11-09T21:46:59.276+0000] {taskinstance.py:2613} INFO - Dependencies all met for dep_context=non-requeueable deps ti=<TaskInstance: dag_with_postgres_operator.insert_into_table scheduled__2024-08-29T00:00:00+00:00 [queued]>
[2024-11-09T21:46:59.325+0000] {taskinstance.py:2613} INFO - Dependencies all met for dep_context=requeueable deps ti=<TaskInstance: dag_with_postgres_operator.insert_into_table scheduled__2024-08-29T00:00:00+00:00 [queued]>
[2024-11-09T21:46:59.335+0000] {taskinstance.py:2866} INFO - Starting attempt 2 of 6
[2024-11-09T21:46:59.463+0000] {taskinstance.py:2889} INFO - Executing <Task(PostgresOperator): insert_into_table> on 2024-08-29 00:00:00+00:00
[2024-11-09T21:46:59.497+0000] {warnings.py:112} WARNING - /home/***/.local/lib/python3.12/site-packages/***/task/task_runner/standard_task_runner.py:70: DeprecationWarning: This process (pid=779) is multi-threaded, use of fork() may lead to deadlocks in the child.
  pid = os.fork()

[2024-11-09T21:46:59.529+0000] {standard_task_runner.py:72} INFO - Started process 801 to run task
[2024-11-09T21:46:59.562+0000] {standard_task_runner.py:104} INFO - Running: ['***', 'tasks', 'run', 'dag_with_postgres_operator', 'insert_into_table', 'scheduled__2024-08-29T00:00:00+00:00', '--job-id', '1582', '--raw', '--subdir', 'DAGS_FOLDER/postgres.py', '--cfg-path', '/tmp/tmpsnpovf4c']
[2024-11-09T21:46:59.583+0000] {standard_task_runner.py:105} INFO - Job 1582: Subtask insert_into_table
[2024-11-09T21:46:59.835+0000] {task_command.py:467} INFO - Running <TaskInstance: dag_with_postgres_operator.insert_into_table scheduled__2024-08-29T00:00:00+00:00 [running]> on host 4778426a6c09
[2024-11-09T21:47:00.292+0000] {taskinstance.py:3132} INFO - Exporting env vars: AIRFLOW_CTX_DAG_OWNER='sumit kumar' AIRFLOW_CTX_DAG_ID='dag_with_postgres_operator' AIRFLOW_CTX_TASK_ID='insert_into_table' AIRFLOW_CTX_EXECUTION_DATE='2024-08-29T00:00:00+00:00' AIRFLOW_CTX_TRY_NUMBER='2' AIRFLOW_CTX_DAG_RUN_ID='scheduled__2024-08-29T00:00:00+00:00'
[2024-11-09T21:47:00.301+0000] {logging_mixin.py:190} INFO - Task instance is in running state
[2024-11-09T21:47:00.302+0000] {logging_mixin.py:190} INFO -  Previous state of the Task instance: queued
[2024-11-09T21:47:00.310+0000] {logging_mixin.py:190} INFO - Current task name:insert_into_table state:running start_date:2024-11-09 21:46:59.285937+00:00
[2024-11-09T21:47:00.311+0000] {logging_mixin.py:190} INFO - Dag name:dag_with_postgres_operator and current dag run status:running
[2024-11-09T21:47:00.314+0000] {taskinstance.py:731} INFO - ::endgroup::
[2024-11-09T21:47:00.320+0000] {sql.py:278} INFO - Executing: 
            insert into Orders values(4,'No delivired')
        
[2024-11-09T21:47:00.350+0000] {base.py:84} INFO - Retrieving connection 'postgres_local'
[2024-11-09T21:47:00.400+0000] {base.py:84} INFO - Retrieving connection 'postgres_local'
[2024-11-09T21:47:00.566+0000] {sql.py:544} INFO - Running statement: 
            insert into Orders values(4,'No delivired')
        , parameters: None
[2024-11-09T21:47:00.588+0000] {taskinstance.py:3311} ERROR - Task failed with exception
Traceback (most recent call last):
  File "/home/airflow/.local/lib/python3.12/site-packages/airflow/models/taskinstance.py", line 767, in _execute_task
    result = _execute_callable(context=context, **execute_callable_kwargs)
             ^^^^^^^^^^^^^^^^^^^^^^^^^^^^^^^^^^^^^^^^^^^^^^^^^^^^^^^^^^^^^
  File "/home/airflow/.local/lib/python3.12/site-packages/airflow/models/taskinstance.py", line 733, in _execute_callable
    return ExecutionCallableRunner(
           ^^^^^^^^^^^^^^^^^^^^^^^^
  File "/home/airflow/.local/lib/python3.12/site-packages/airflow/utils/operator_helpers.py", line 252, in run
    return self.func(*args, **kwargs)
           ^^^^^^^^^^^^^^^^^^^^^^^^^^
  File "/home/airflow/.local/lib/python3.12/site-packages/airflow/models/baseoperator.py", line 417, in wrapper
    return func(self, *args, **kwargs)
           ^^^^^^^^^^^^^^^^^^^^^^^^^^^
  File "/home/airflow/.local/lib/python3.12/site-packages/airflow/providers/common/sql/operators/sql.py", line 284, in execute
    output = hook.run(
             ^^^^^^^^^
  File "/home/airflow/.local/lib/python3.12/site-packages/airflow/providers/common/sql/hooks/sql.py", line 489, in run
    self._run_command(cur, sql_statement, parameters)
  File "/home/airflow/.local/lib/python3.12/site-packages/airflow/providers/common/sql/hooks/sql.py", line 549, in _run_command
    cur.execute(sql_statement)
psycopg2.errors.UniqueViolation: duplicate key value violates unique constraint "orders_pkey"
DETAIL:  Key (orderid)=(4) already exists.

[2024-11-09T21:47:00.651+0000] {logging_mixin.py:190} INFO - Task instance in failure state
[2024-11-09T21:47:00.673+0000] {logging_mixin.py:190} INFO - Task start:2024-11-09 21:46:59.285937+00:00 end:2024-11-09 21:47:00.650367+00:00 duration:1.36443
[2024-11-09T21:47:00.676+0000] {logging_mixin.py:190} INFO - Task:<Task(PostgresOperator): insert_into_table> dag:<DAG: dag_with_postgres_operator> dagrun:<DagRun dag_with_postgres_operator @ 2024-08-29 00:00:00+00:00: scheduled__2024-08-29T00:00:00+00:00, state:running, queued_at: 2024-11-09 21:45:26.819144+00:00. externally triggered: False>
[2024-11-09T21:47:00.677+0000] {logging_mixin.py:190} INFO - Failure caused by duplicate key value violates unique constraint "orders_pkey"
DETAIL:  Key (orderid)=(4) already exists.
[2024-11-09T21:47:00.678+0000] {taskinstance.py:1225} INFO - Marking task as UP_FOR_RETRY. dag_id=dag_with_postgres_operator, task_id=insert_into_table, run_id=scheduled__2024-08-29T00:00:00+00:00, execution_date=20240829T000000, start_date=20241109T214659, end_date=20241109T214700
[2024-11-09T21:47:00.834+0000] {taskinstance.py:340} INFO - ::group::Post task execution logs
[2024-11-09T21:47:00.838+0000] {standard_task_runner.py:124} ERROR - Failed to execute job 1582 for task insert_into_table (duplicate key value violates unique constraint "orders_pkey"
DETAIL:  Key (orderid)=(4) already exists.
; 801)
Traceback (most recent call last):
  File "/home/airflow/.local/lib/python3.12/site-packages/airflow/task/task_runner/standard_task_runner.py", line 117, in _start_by_fork
    ret = args.func(args, dag=self.dag)
          ^^^^^^^^^^^^^^^^^^^^^^^^^^^^^
  File "/home/airflow/.local/lib/python3.12/site-packages/airflow/cli/cli_config.py", line 49, in command
    return func(*args, **kwargs)
           ^^^^^^^^^^^^^^^^^^^^^
  File "/home/airflow/.local/lib/python3.12/site-packages/airflow/utils/cli.py", line 116, in wrapper
    return f(*args, **kwargs)
           ^^^^^^^^^^^^^^^^^^
  File "/home/airflow/.local/lib/python3.12/site-packages/airflow/cli/commands/task_command.py", line 483, in task_run
    task_return_code = _run_task_by_selected_method(args, _dag, ti)
                       ^^^^^^^^^^^^^^^^^^^^^^^^^^^^^^^^^^^^^^^^^^^^
  File "/home/airflow/.local/lib/python3.12/site-packages/airflow/cli/commands/task_command.py", line 256, in _run_task_by_selected_method
    return _run_raw_task(args, ti)
           ^^^^^^^^^^^^^^^^^^^^^^^
  File "/home/airflow/.local/lib/python3.12/site-packages/airflow/cli/commands/task_command.py", line 341, in _run_raw_task
    return ti._run_raw_task(
           ^^^^^^^^^^^^^^^^^
  File "/home/airflow/.local/lib/python3.12/site-packages/airflow/utils/session.py", line 97, in wrapper
    return func(*args, session=session, **kwargs)
           ^^^^^^^^^^^^^^^^^^^^^^^^^^^^^^^^^^^^^^
  File "/home/airflow/.local/lib/python3.12/site-packages/airflow/models/taskinstance.py", line 3005, in _run_raw_task
    return _run_raw_task(
           ^^^^^^^^^^^^^^
  File "/home/airflow/.local/lib/python3.12/site-packages/airflow/models/taskinstance.py", line 273, in _run_raw_task
    TaskInstance._execute_task_with_callbacks(
  File "/home/airflow/.local/lib/python3.12/site-packages/airflow/models/taskinstance.py", line 3159, in _execute_task_with_callbacks
    result = self._execute_task(context, task_orig)
             ^^^^^^^^^^^^^^^^^^^^^^^^^^^^^^^^^^^^^^
  File "/home/airflow/.local/lib/python3.12/site-packages/airflow/models/taskinstance.py", line 3183, in _execute_task
    return _execute_task(self, context, task_orig)
           ^^^^^^^^^^^^^^^^^^^^^^^^^^^^^^^^^^^^^^^
  File "/home/airflow/.local/lib/python3.12/site-packages/airflow/models/taskinstance.py", line 767, in _execute_task
    result = _execute_callable(context=context, **execute_callable_kwargs)
             ^^^^^^^^^^^^^^^^^^^^^^^^^^^^^^^^^^^^^^^^^^^^^^^^^^^^^^^^^^^^^
  File "/home/airflow/.local/lib/python3.12/site-packages/airflow/models/taskinstance.py", line 733, in _execute_callable
    return ExecutionCallableRunner(
           ^^^^^^^^^^^^^^^^^^^^^^^^
  File "/home/airflow/.local/lib/python3.12/site-packages/airflow/utils/operator_helpers.py", line 252, in run
    return self.func(*args, **kwargs)
           ^^^^^^^^^^^^^^^^^^^^^^^^^^
  File "/home/airflow/.local/lib/python3.12/site-packages/airflow/models/baseoperator.py", line 417, in wrapper
    return func(self, *args, **kwargs)
           ^^^^^^^^^^^^^^^^^^^^^^^^^^^
  File "/home/airflow/.local/lib/python3.12/site-packages/airflow/providers/common/sql/operators/sql.py", line 284, in execute
    output = hook.run(
             ^^^^^^^^^
  File "/home/airflow/.local/lib/python3.12/site-packages/airflow/providers/common/sql/hooks/sql.py", line 489, in run
    self._run_command(cur, sql_statement, parameters)
  File "/home/airflow/.local/lib/python3.12/site-packages/airflow/providers/common/sql/hooks/sql.py", line 549, in _run_command
    cur.execute(sql_statement)
psycopg2.errors.UniqueViolation: duplicate key value violates unique constraint "orders_pkey"
DETAIL:  Key (orderid)=(4) already exists.

[2024-11-09T21:47:00.885+0000] {local_task_job_runner.py:266} INFO - Task exited with return code 1
[2024-11-09T21:47:00.969+0000] {taskinstance.py:3895} INFO - 0 downstream tasks scheduled from follow-on schedule check
[2024-11-09T21:47:00.988+0000] {local_task_job_runner.py:245} INFO - ::endgroup::
