[2024-11-07T20:12:37.163+0000] {local_task_job_runner.py:123} INFO - ::group::Pre task execution logs
[2024-11-07T20:12:37.196+0000] {taskinstance.py:2613} INFO - Dependencies all met for dep_context=non-requeueable deps ti=<TaskInstance: dag_with_postgres_operator.insert_into_table scheduled__2024-05-08T00:00:00+00:00 [queued]>
[2024-11-07T20:12:37.213+0000] {taskinstance.py:2613} INFO - Dependencies all met for dep_context=requeueable deps ti=<TaskInstance: dag_with_postgres_operator.insert_into_table scheduled__2024-05-08T00:00:00+00:00 [queued]>
[2024-11-07T20:12:37.218+0000] {taskinstance.py:2866} INFO - Starting attempt 3 of 6
[2024-11-07T20:12:37.244+0000] {taskinstance.py:2889} INFO - Executing <Task(PostgresOperator): insert_into_table> on 2024-05-08 00:00:00+00:00
[2024-11-07T20:12:37.257+0000] {warnings.py:112} WARNING - /home/***/.local/lib/python3.12/site-packages/***/task/task_runner/standard_task_runner.py:70: DeprecationWarning: This process (pid=686) is multi-threaded, use of fork() may lead to deadlocks in the child.
  pid = os.fork()

[2024-11-07T20:12:37.260+0000] {standard_task_runner.py:72} INFO - Started process 700 to run task
[2024-11-07T20:12:37.261+0000] {standard_task_runner.py:104} INFO - Running: ['***', 'tasks', 'run', 'dag_with_postgres_operator', 'insert_into_table', 'scheduled__2024-05-08T00:00:00+00:00', '--job-id', '742', '--raw', '--subdir', 'DAGS_FOLDER/postgres.py', '--cfg-path', '/tmp/tmphiqfnsxf']
[2024-11-07T20:12:37.264+0000] {standard_task_runner.py:105} INFO - Job 742: Subtask insert_into_table
[2024-11-07T20:12:37.336+0000] {task_command.py:467} INFO - Running <TaskInstance: dag_with_postgres_operator.insert_into_table scheduled__2024-05-08T00:00:00+00:00 [running]> on host 3f85553e814e
[2024-11-07T20:12:37.846+0000] {taskinstance.py:3132} INFO - Exporting env vars: AIRFLOW_CTX_DAG_OWNER='sumit kumar' AIRFLOW_CTX_DAG_ID='dag_with_postgres_operator' AIRFLOW_CTX_TASK_ID='insert_into_table' AIRFLOW_CTX_EXECUTION_DATE='2024-05-08T00:00:00+00:00' AIRFLOW_CTX_TRY_NUMBER='3' AIRFLOW_CTX_DAG_RUN_ID='scheduled__2024-05-08T00:00:00+00:00'
[2024-11-07T20:12:37.848+0000] {logging_mixin.py:190} INFO - Task instance is in running state
[2024-11-07T20:12:37.848+0000] {logging_mixin.py:190} INFO -  Previous state of the Task instance: queued
[2024-11-07T20:12:37.849+0000] {logging_mixin.py:190} INFO - Current task name:insert_into_table state:running start_date:2024-11-07 20:12:37.198025+00:00
[2024-11-07T20:12:37.850+0000] {logging_mixin.py:190} INFO - Dag name:dag_with_postgres_operator and current dag run status:running
[2024-11-07T20:12:37.851+0000] {taskinstance.py:731} INFO - ::endgroup::
[2024-11-07T20:12:37.852+0000] {sql.py:278} INFO - Executing: 
            insert into Orders values(4,'No delivired')
        
[2024-11-07T20:12:37.865+0000] {base.py:84} INFO - Retrieving connection 'postgres_local'
[2024-11-07T20:12:37.881+0000] {base.py:84} INFO - Retrieving connection 'postgres_local'
[2024-11-07T20:12:37.896+0000] {sql.py:544} INFO - Running statement: 
            insert into Orders values(4,'No delivired')
        , parameters: None
[2024-11-07T20:12:37.902+0000] {taskinstance.py:3311} ERROR - Task failed with exception
Traceback (most recent call last):
  File "/home/airflow/.local/lib/python3.12/site-packages/airflow/models/taskinstance.py", line 767, in _execute_task
    result = _execute_callable(context=context, **execute_callable_kwargs)
             ^^^^^^^^^^^^^^^^^^^^^^^^^^^^^^^^^^^^^^^^^^^^^^^^^^^^^^^^^^^^^
  File "/home/airflow/.local/lib/python3.12/site-packages/airflow/models/taskinstance.py", line 733, in _execute_callable
    return ExecutionCallableRunner(
           ^^^^^^^^^^^^^^^^^^^^^^^^
  File "/home/airflow/.local/lib/python3.12/site-packages/airflow/utils/operator_helpers.py", line 252, in run
    return self.func(*args, **kwargs)
           ^^^^^^^^^^^^^^^^^^^^^^^^^^
  File "/home/airflow/.local/lib/python3.12/site-packages/airflow/models/baseoperator.py", line 417, in wrapper
    return func(self, *args, **kwargs)
           ^^^^^^^^^^^^^^^^^^^^^^^^^^^
  File "/home/airflow/.local/lib/python3.12/site-packages/airflow/providers/common/sql/operators/sql.py", line 284, in execute
    output = hook.run(
             ^^^^^^^^^
  File "/home/airflow/.local/lib/python3.12/site-packages/airflow/providers/common/sql/hooks/sql.py", line 489, in run
    self._run_command(cur, sql_statement, parameters)
  File "/home/airflow/.local/lib/python3.12/site-packages/airflow/providers/common/sql/hooks/sql.py", line 549, in _run_command
    cur.execute(sql_statement)
psycopg2.errors.UniqueViolation: duplicate key value violates unique constraint "orders_pkey"
DETAIL:  Key (orderid)=(4) already exists.

[2024-11-07T20:12:37.929+0000] {logging_mixin.py:190} INFO - Task instance in failure state
[2024-11-07T20:12:37.930+0000] {logging_mixin.py:190} INFO - Task start:2024-11-07 20:12:37.198025+00:00 end:2024-11-07 20:12:37.928087+00:00 duration:0.730062
[2024-11-07T20:12:37.931+0000] {logging_mixin.py:190} INFO - Task:<Task(PostgresOperator): insert_into_table> dag:<DAG: dag_with_postgres_operator> dagrun:<DagRun dag_with_postgres_operator @ 2024-05-08 00:00:00+00:00: scheduled__2024-05-08T00:00:00+00:00, state:running, queued_at: 2024-11-07 20:10:13.811491+00:00. externally triggered: False>
[2024-11-07T20:12:37.932+0000] {logging_mixin.py:190} INFO - Failure caused by duplicate key value violates unique constraint "orders_pkey"
DETAIL:  Key (orderid)=(4) already exists.
[2024-11-07T20:12:37.934+0000] {taskinstance.py:1225} INFO - Marking task as UP_FOR_RETRY. dag_id=dag_with_postgres_operator, task_id=insert_into_table, run_id=scheduled__2024-05-08T00:00:00+00:00, execution_date=20240508T000000, start_date=20241107T201237, end_date=20241107T201237
[2024-11-07T20:12:37.966+0000] {taskinstance.py:340} INFO - ::group::Post task execution logs
[2024-11-07T20:12:37.968+0000] {standard_task_runner.py:124} ERROR - Failed to execute job 742 for task insert_into_table (duplicate key value violates unique constraint "orders_pkey"
DETAIL:  Key (orderid)=(4) already exists.
; 700)
Traceback (most recent call last):
  File "/home/airflow/.local/lib/python3.12/site-packages/airflow/task/task_runner/standard_task_runner.py", line 117, in _start_by_fork
    ret = args.func(args, dag=self.dag)
          ^^^^^^^^^^^^^^^^^^^^^^^^^^^^^
  File "/home/airflow/.local/lib/python3.12/site-packages/airflow/cli/cli_config.py", line 49, in command
    return func(*args, **kwargs)
           ^^^^^^^^^^^^^^^^^^^^^
  File "/home/airflow/.local/lib/python3.12/site-packages/airflow/utils/cli.py", line 116, in wrapper
    return f(*args, **kwargs)
           ^^^^^^^^^^^^^^^^^^
  File "/home/airflow/.local/lib/python3.12/site-packages/airflow/cli/commands/task_command.py", line 483, in task_run
    task_return_code = _run_task_by_selected_method(args, _dag, ti)
                       ^^^^^^^^^^^^^^^^^^^^^^^^^^^^^^^^^^^^^^^^^^^^
  File "/home/airflow/.local/lib/python3.12/site-packages/airflow/cli/commands/task_command.py", line 256, in _run_task_by_selected_method
    return _run_raw_task(args, ti)
           ^^^^^^^^^^^^^^^^^^^^^^^
  File "/home/airflow/.local/lib/python3.12/site-packages/airflow/cli/commands/task_command.py", line 341, in _run_raw_task
    return ti._run_raw_task(
           ^^^^^^^^^^^^^^^^^
  File "/home/airflow/.local/lib/python3.12/site-packages/airflow/utils/session.py", line 97, in wrapper
    return func(*args, session=session, **kwargs)
           ^^^^^^^^^^^^^^^^^^^^^^^^^^^^^^^^^^^^^^
  File "/home/airflow/.local/lib/python3.12/site-packages/airflow/models/taskinstance.py", line 3005, in _run_raw_task
    return _run_raw_task(
           ^^^^^^^^^^^^^^
  File "/home/airflow/.local/lib/python3.12/site-packages/airflow/models/taskinstance.py", line 273, in _run_raw_task
    TaskInstance._execute_task_with_callbacks(
  File "/home/airflow/.local/lib/python3.12/site-packages/airflow/models/taskinstance.py", line 3159, in _execute_task_with_callbacks
    result = self._execute_task(context, task_orig)
             ^^^^^^^^^^^^^^^^^^^^^^^^^^^^^^^^^^^^^^
  File "/home/airflow/.local/lib/python3.12/site-packages/airflow/models/taskinstance.py", line 3183, in _execute_task
    return _execute_task(self, context, task_orig)
           ^^^^^^^^^^^^^^^^^^^^^^^^^^^^^^^^^^^^^^^
  File "/home/airflow/.local/lib/python3.12/site-packages/airflow/models/taskinstance.py", line 767, in _execute_task
    result = _execute_callable(context=context, **execute_callable_kwargs)
             ^^^^^^^^^^^^^^^^^^^^^^^^^^^^^^^^^^^^^^^^^^^^^^^^^^^^^^^^^^^^^
  File "/home/airflow/.local/lib/python3.12/site-packages/airflow/models/taskinstance.py", line 733, in _execute_callable
    return ExecutionCallableRunner(
           ^^^^^^^^^^^^^^^^^^^^^^^^
  File "/home/airflow/.local/lib/python3.12/site-packages/airflow/utils/operator_helpers.py", line 252, in run
    return self.func(*args, **kwargs)
           ^^^^^^^^^^^^^^^^^^^^^^^^^^
  File "/home/airflow/.local/lib/python3.12/site-packages/airflow/models/baseoperator.py", line 417, in wrapper
    return func(self, *args, **kwargs)
           ^^^^^^^^^^^^^^^^^^^^^^^^^^^
  File "/home/airflow/.local/lib/python3.12/site-packages/airflow/providers/common/sql/operators/sql.py", line 284, in execute
    output = hook.run(
             ^^^^^^^^^
  File "/home/airflow/.local/lib/python3.12/site-packages/airflow/providers/common/sql/hooks/sql.py", line 489, in run
    self._run_command(cur, sql_statement, parameters)
  File "/home/airflow/.local/lib/python3.12/site-packages/airflow/providers/common/sql/hooks/sql.py", line 549, in _run_command
    cur.execute(sql_statement)
psycopg2.errors.UniqueViolation: duplicate key value violates unique constraint "orders_pkey"
DETAIL:  Key (orderid)=(4) already exists.

[2024-11-07T20:12:37.999+0000] {local_task_job_runner.py:266} INFO - Task exited with return code 1
[2024-11-07T20:12:38.017+0000] {local_task_job_runner.py:245} INFO - ::endgroup::
[2024-11-09T20:54:40.954+0000] {local_task_job_runner.py:123} INFO - ::group::Pre task execution logs
[2024-11-09T20:54:41.027+0000] {taskinstance.py:2613} INFO - Dependencies all met for dep_context=non-requeueable deps ti=<TaskInstance: dag_with_postgres_operator.insert_into_table scheduled__2024-05-08T00:00:00+00:00 [queued]>
[2024-11-09T20:54:41.066+0000] {taskinstance.py:2613} INFO - Dependencies all met for dep_context=requeueable deps ti=<TaskInstance: dag_with_postgres_operator.insert_into_table scheduled__2024-05-08T00:00:00+00:00 [queued]>
[2024-11-09T20:54:41.068+0000] {taskinstance.py:2866} INFO - Starting attempt 3 of 6
[2024-11-09T20:54:41.159+0000] {taskinstance.py:2889} INFO - Executing <Task(PostgresOperator): insert_into_table> on 2024-05-08 00:00:00+00:00
[2024-11-09T20:54:41.179+0000] {warnings.py:112} WARNING - /home/***/.local/lib/python3.12/site-packages/***/task/task_runner/standard_task_runner.py:70: DeprecationWarning: This process (pid=3338) is multi-threaded, use of fork() may lead to deadlocks in the child.
  pid = os.fork()

[2024-11-09T20:54:41.185+0000] {standard_task_runner.py:72} INFO - Started process 3357 to run task
[2024-11-09T20:54:41.195+0000] {standard_task_runner.py:104} INFO - Running: ['***', 'tasks', 'run', 'dag_with_postgres_operator', 'insert_into_table', 'scheduled__2024-05-08T00:00:00+00:00', '--job-id', '820', '--raw', '--subdir', 'DAGS_FOLDER/postgres.py', '--cfg-path', '/tmp/tmpe3a0bun3']
[2024-11-09T20:54:41.202+0000] {standard_task_runner.py:105} INFO - Job 820: Subtask insert_into_table
[2024-11-09T20:54:41.433+0000] {task_command.py:467} INFO - Running <TaskInstance: dag_with_postgres_operator.insert_into_table scheduled__2024-05-08T00:00:00+00:00 [running]> on host 7a581205cd28
[2024-11-09T20:54:42.040+0000] {taskinstance.py:3132} INFO - Exporting env vars: AIRFLOW_CTX_DAG_OWNER='sumit kumar' AIRFLOW_CTX_DAG_ID='dag_with_postgres_operator' AIRFLOW_CTX_TASK_ID='insert_into_table' AIRFLOW_CTX_EXECUTION_DATE='2024-05-08T00:00:00+00:00' AIRFLOW_CTX_TRY_NUMBER='3' AIRFLOW_CTX_DAG_RUN_ID='scheduled__2024-05-08T00:00:00+00:00'
[2024-11-09T20:54:42.061+0000] {logging_mixin.py:190} INFO - Task instance is in running state
[2024-11-09T20:54:42.062+0000] {logging_mixin.py:190} INFO -  Previous state of the Task instance: queued
[2024-11-09T20:54:42.064+0000] {logging_mixin.py:190} INFO - Current task name:insert_into_table state:running start_date:2024-11-09 20:54:41.037806+00:00
[2024-11-09T20:54:42.066+0000] {logging_mixin.py:190} INFO - Dag name:dag_with_postgres_operator and current dag run status:running
[2024-11-09T20:54:42.067+0000] {taskinstance.py:731} INFO - ::endgroup::
[2024-11-09T20:54:42.068+0000] {sql.py:278} INFO - Executing: 
            insert into Orders values(4,'No delivired')
        
[2024-11-09T20:54:42.094+0000] {base.py:84} INFO - Retrieving connection 'postgres_local'
[2024-11-09T20:54:42.127+0000] {base.py:84} INFO - Retrieving connection 'postgres_local'
[2024-11-09T20:54:42.164+0000] {sql.py:544} INFO - Running statement: 
            insert into Orders values(4,'No delivired')
        , parameters: None
[2024-11-09T20:54:42.172+0000] {taskinstance.py:3311} ERROR - Task failed with exception
Traceback (most recent call last):
  File "/home/airflow/.local/lib/python3.12/site-packages/airflow/models/taskinstance.py", line 767, in _execute_task
    result = _execute_callable(context=context, **execute_callable_kwargs)
             ^^^^^^^^^^^^^^^^^^^^^^^^^^^^^^^^^^^^^^^^^^^^^^^^^^^^^^^^^^^^^
  File "/home/airflow/.local/lib/python3.12/site-packages/airflow/models/taskinstance.py", line 733, in _execute_callable
    return ExecutionCallableRunner(
           ^^^^^^^^^^^^^^^^^^^^^^^^
  File "/home/airflow/.local/lib/python3.12/site-packages/airflow/utils/operator_helpers.py", line 252, in run
    return self.func(*args, **kwargs)
           ^^^^^^^^^^^^^^^^^^^^^^^^^^
  File "/home/airflow/.local/lib/python3.12/site-packages/airflow/models/baseoperator.py", line 417, in wrapper
    return func(self, *args, **kwargs)
           ^^^^^^^^^^^^^^^^^^^^^^^^^^^
  File "/home/airflow/.local/lib/python3.12/site-packages/airflow/providers/common/sql/operators/sql.py", line 284, in execute
    output = hook.run(
             ^^^^^^^^^
  File "/home/airflow/.local/lib/python3.12/site-packages/airflow/providers/common/sql/hooks/sql.py", line 489, in run
    self._run_command(cur, sql_statement, parameters)
  File "/home/airflow/.local/lib/python3.12/site-packages/airflow/providers/common/sql/hooks/sql.py", line 549, in _run_command
    cur.execute(sql_statement)
psycopg2.errors.UniqueViolation: duplicate key value violates unique constraint "orders_pkey"
DETAIL:  Key (orderid)=(4) already exists.

[2024-11-09T20:54:42.216+0000] {logging_mixin.py:190} INFO - Task instance in failure state
[2024-11-09T20:54:42.218+0000] {logging_mixin.py:190} INFO - Task start:2024-11-09 20:54:41.037806+00:00 end:2024-11-09 20:54:42.211805+00:00 duration:1.173999
[2024-11-09T20:54:42.226+0000] {logging_mixin.py:190} INFO - Task:<Task(PostgresOperator): insert_into_table> dag:<DAG: dag_with_postgres_operator> dagrun:<DagRun dag_with_postgres_operator @ 2024-05-08 00:00:00+00:00: scheduled__2024-05-08T00:00:00+00:00, state:running, queued_at: 2024-11-09 20:52:07.166442+00:00. externally triggered: False>
[2024-11-09T20:54:42.265+0000] {logging_mixin.py:190} INFO - Failure caused by duplicate key value violates unique constraint "orders_pkey"
DETAIL:  Key (orderid)=(4) already exists.
[2024-11-09T20:54:42.274+0000] {taskinstance.py:1225} INFO - Marking task as UP_FOR_RETRY. dag_id=dag_with_postgres_operator, task_id=insert_into_table, run_id=scheduled__2024-05-08T00:00:00+00:00, execution_date=20240508T000000, start_date=20241109T205441, end_date=20241109T205442
[2024-11-09T20:54:42.319+0000] {taskinstance.py:340} INFO - ::group::Post task execution logs
[2024-11-09T20:54:42.320+0000] {standard_task_runner.py:124} ERROR - Failed to execute job 820 for task insert_into_table (duplicate key value violates unique constraint "orders_pkey"
DETAIL:  Key (orderid)=(4) already exists.
; 3357)
Traceback (most recent call last):
  File "/home/airflow/.local/lib/python3.12/site-packages/airflow/task/task_runner/standard_task_runner.py", line 117, in _start_by_fork
    ret = args.func(args, dag=self.dag)
          ^^^^^^^^^^^^^^^^^^^^^^^^^^^^^
  File "/home/airflow/.local/lib/python3.12/site-packages/airflow/cli/cli_config.py", line 49, in command
    return func(*args, **kwargs)
           ^^^^^^^^^^^^^^^^^^^^^
  File "/home/airflow/.local/lib/python3.12/site-packages/airflow/utils/cli.py", line 116, in wrapper
    return f(*args, **kwargs)
           ^^^^^^^^^^^^^^^^^^
  File "/home/airflow/.local/lib/python3.12/site-packages/airflow/cli/commands/task_command.py", line 483, in task_run
    task_return_code = _run_task_by_selected_method(args, _dag, ti)
                       ^^^^^^^^^^^^^^^^^^^^^^^^^^^^^^^^^^^^^^^^^^^^
  File "/home/airflow/.local/lib/python3.12/site-packages/airflow/cli/commands/task_command.py", line 256, in _run_task_by_selected_method
    return _run_raw_task(args, ti)
           ^^^^^^^^^^^^^^^^^^^^^^^
  File "/home/airflow/.local/lib/python3.12/site-packages/airflow/cli/commands/task_command.py", line 341, in _run_raw_task
    return ti._run_raw_task(
           ^^^^^^^^^^^^^^^^^
  File "/home/airflow/.local/lib/python3.12/site-packages/airflow/utils/session.py", line 97, in wrapper
    return func(*args, session=session, **kwargs)
           ^^^^^^^^^^^^^^^^^^^^^^^^^^^^^^^^^^^^^^
  File "/home/airflow/.local/lib/python3.12/site-packages/airflow/models/taskinstance.py", line 3005, in _run_raw_task
    return _run_raw_task(
           ^^^^^^^^^^^^^^
  File "/home/airflow/.local/lib/python3.12/site-packages/airflow/models/taskinstance.py", line 273, in _run_raw_task
    TaskInstance._execute_task_with_callbacks(
  File "/home/airflow/.local/lib/python3.12/site-packages/airflow/models/taskinstance.py", line 3159, in _execute_task_with_callbacks
    result = self._execute_task(context, task_orig)
             ^^^^^^^^^^^^^^^^^^^^^^^^^^^^^^^^^^^^^^
  File "/home/airflow/.local/lib/python3.12/site-packages/airflow/models/taskinstance.py", line 3183, in _execute_task
    return _execute_task(self, context, task_orig)
           ^^^^^^^^^^^^^^^^^^^^^^^^^^^^^^^^^^^^^^^
  File "/home/airflow/.local/lib/python3.12/site-packages/airflow/models/taskinstance.py", line 767, in _execute_task
    result = _execute_callable(context=context, **execute_callable_kwargs)
             ^^^^^^^^^^^^^^^^^^^^^^^^^^^^^^^^^^^^^^^^^^^^^^^^^^^^^^^^^^^^^
  File "/home/airflow/.local/lib/python3.12/site-packages/airflow/models/taskinstance.py", line 733, in _execute_callable
    return ExecutionCallableRunner(
           ^^^^^^^^^^^^^^^^^^^^^^^^
  File "/home/airflow/.local/lib/python3.12/site-packages/airflow/utils/operator_helpers.py", line 252, in run
    return self.func(*args, **kwargs)
           ^^^^^^^^^^^^^^^^^^^^^^^^^^
  File "/home/airflow/.local/lib/python3.12/site-packages/airflow/models/baseoperator.py", line 417, in wrapper
    return func(self, *args, **kwargs)
           ^^^^^^^^^^^^^^^^^^^^^^^^^^^
  File "/home/airflow/.local/lib/python3.12/site-packages/airflow/providers/common/sql/operators/sql.py", line 284, in execute
    output = hook.run(
             ^^^^^^^^^
  File "/home/airflow/.local/lib/python3.12/site-packages/airflow/providers/common/sql/hooks/sql.py", line 489, in run
    self._run_command(cur, sql_statement, parameters)
  File "/home/airflow/.local/lib/python3.12/site-packages/airflow/providers/common/sql/hooks/sql.py", line 549, in _run_command
    cur.execute(sql_statement)
psycopg2.errors.UniqueViolation: duplicate key value violates unique constraint "orders_pkey"
DETAIL:  Key (orderid)=(4) already exists.

[2024-11-09T20:54:42.343+0000] {local_task_job_runner.py:266} INFO - Task exited with return code 1
[2024-11-09T20:54:42.380+0000] {taskinstance.py:3895} INFO - 0 downstream tasks scheduled from follow-on schedule check
[2024-11-09T20:54:42.392+0000] {local_task_job_runner.py:245} INFO - ::endgroup::
